Workbook

Sheet Read Me
A1: RISE vs Competitors — Watchlist Performance Benchmark
A2: Module Watchlist on OPPO CPH3009. Generated by build_report.py from runs.csv; do not edit by hand.
A4: How to read this workbook
A5: 1. 'Test Setup' shows the phone, network and accounts, from env.csv.
A6: 2. 'Metric Catalogue' lists every metric, the tool, and the exact method (same text as METRICS.md).
A7: 3. Data tabs (1–9) hold every run next to its median, so any figure can be traced to runs.csv and its artifact.
A8: 4. 'Summary' shows medians per app, the best app, RISE's rank and gap per metric.
A9: 5. 'Scorecard' turns everything into one 0–100 score per app and ranks them. Weights come from weights.json.
A10: 6. Blank cells are metrics not yet measured. Metrics that do not apply to this module are left out (see METRICS.md).
A12: Legend
A13: Yellow cell, blue text | B13: Value from runs.csv / env.csv
A14: Black text | B14: Formula
A15: Green text | B15: Pulled from another tab
A16: Blue rows / column | B16: RISE (our app)
A17: Red Variation | B17: Runs differ by more than 20%: redo that row
A19: Tools
A20: Tool | B20: Runs on | C20: Used for | D20: Get it
A21: ADB (Android Platform Tools) | B21: Mac | C21: Launch time, lock contention, RAM, bytes, CPU, battery, crashes | D21: brew install android-platform-tools
A22: scrcpy | B22: Mac | C22: Screen recording to count frames for screen-load and tick timings | D22: brew install scrcpy
A23: ffmpeg | B23: Mac | C23: Wasted-redraw analysis of idle recordings (U5) | D23: brew install ffmpeg
A24: Perfetto (Python package) | B24: Mac | C24: Reads the frame traces bench.py records | D24: pip3 install --user perfetto
A25: bench.py / record.py / preflight.py | B25: Mac | C25: Automates the measured metrics and records the manual ones | D25: In this folder
A26: PCAPdroid | B26: Phone | C26: Connections and domains per app, without root | D26: Play Store
A27: LibChecker | B27: Phone | C27: SDKs, native libraries, framework | D27: Play Store / F-Droid
A28: Exodus Privacy | B28: Web | C28: Trackers and permissions in each Play Store APK | D28: exodus-privacy.eu.org

Sheet Summary
A1: RISE vs Competitors — Watchlist Performance Benchmark
A2: Medians from the data tabs, measured on OPPO CPH3009. Green = best, red = worst in each row. RISE is in the blue column.
A3: Device: | C3: OPPO CPH3009 | D3: ← the phone this module was measured on (one per module; see README on comparing across phones)
A4: RISE is best in: | C4: =COUNTIF(M7:M56,"RISE")&" of "&COUNTIF(O7:O56,">0")&" metrics measured" | H4: Average RISE rank: | J4: =IFERROR(AVERAGE(N7:N56),"–")
A6: ID | B6: Category | C6: Metric | D6: Unit | E6: Better | F6: RISE | G6: Kite | H6: Groww | I6: Angel One | J6: INDmoney | K6: Kotak Neo | L6: SAHI | M6: Best app | N6: RISE rank | O6: Apps measured | P6: RISE gap vs best
A7: ='Metric Catalogue'!A5 | B7: ='Metric Catalogue'!B5 | C7: ='Metric Catalogue'!C5 | D7: ='Metric Catalogue'!D5 | E7: ='Metric Catalogue'!E5 | F7: =IFERROR(INDEX('1 Load & Network'!$L$5:$L$109,MATCH($A7&"|"&F$6&"|"&$C$3,'1 Load & Network'!$F$5:$F$109,0)),"") | G7: =IFERROR(INDEX('1 Load & Network'!$L$5:$L$109,MATCH($A7&"|"&G$6&"|"&$C$3,'1 Load & Network'!$F$5:$F$109,0)),"") | H7: =IFERROR(INDEX('1 Load & Network'!$L$5:$L$109,MATCH($A7&"|"&H$6&"|"&$C$3,'1 Load & Network'!$F$5:$F$109,0)),"") | I7: =IFERROR(INDEX('1 Load & Network'!$L$5:$L$109,MATCH($A7&"|"&I$6&"|"&$C$3,'1 Load & Network'!$F$5:$F$109,0)),"") | J7: =IFERROR(INDEX('1 Load & Network'!$L$5:$L$109,MATCH($A7&"|"&J$6&"|"&$C$3,'1 Load & Network'!$F$5:$F$109,0)),"") | K7: =IFERROR(INDEX('1 Load & Network'!$L$5:$L$109,MATCH($A7&"|"&K$6&"|"&$C$3,'1 Load & Network'!$F$5:$F$109,0)),"") | L7: =IFERROR(INDEX('1 Load & Network'!$L$5:$L$109,MATCH($A7&"|"&L$6&"|"&$C$3,'1 Load & Network'!$F$5:$F$109,0)),"") | M7: =IF(COUNT(F7:L7)=0,"",INDEX($F$6:$L$6,MATCH(IF($E7="Lower",MIN(F7:L7),MAX(F7:L7)),F7:L7,0))) | N7: =IF(OR(F7="",COUNT(F7:L7)=0),"",IF($E7="Lower",COUNTIF(F7:L7,"<"&F7),COUNTIF(F7:L7,">"&F7))+1) | O7: =COUNT(F7:L7) | P7: =IF(OR(F7="",COUNT(F7:L7)<2),"",IF($E7="Lower",IF(MIN(F7:L7)=0,"",(F7-MIN(F7:L7))/MIN(F7:L7)),IF(MAX(F7:L7)=0,"",(MAX(F7:L7)-F7)/MAX(F7:L7))))
A8: ='Metric Catalogue'!A6 | B8: ='Metric Catalogue'!B6 | C8: ='Metric Catalogue'!C6 | D8: ='Metric Catalogue'!D6 | E8: ='Metric Catalogue'!E6 | F8: =IFERROR(INDEX('1 Load & Network'!$L$5:$L$109,MATCH($A8&"|"&F$6&"|"&$C$3,'1 Load & Network'!$F$5:$F$109,0)),"") | G8: =IFERROR(INDEX('1 Load & Network'!$L$5:$L$109,MATCH($A8&"|"&G$6&"|"&$C$3,'1 Load & Network'!$F$5:$F$109,0)),"") | H8: =IFERROR(INDEX('1 Load & Network'!$L$5:$L$109,MATCH($A8&"|"&H$6&"|"&$C$3,'1 Load & Network'!$F$5:$F$109,0)),"") | I8: =IFERROR(INDEX('1 Load & Network'!$L$5:$L$109,MATCH($A8&"|"&I$6&"|"&$C$3,'1 Load & Network'!$F$5:$F$109,0)),"") | J8: =IFERROR(INDEX('1 Load & Network'!$L$5:$L$109,MATCH($A8&"|"&J$6&"|"&$C$3,'1 Load & Network'!$F$5:$F$109,0)),"") | K8: =IFERROR(INDEX('1 Load & Network'!$L$5:$L$109,MATCH($A8&"|"&K$6&"|"&$C$3,'1 Load & Network'!$F$5:$F$109,0)),"") | L8: =IFERROR(INDEX('1 Load & Network'!$L$5:$L$109,MATCH($A8&"|"&L$6&"|"&$C$3,'1 Load & Network'!$F$5:$F$109,0)),"") | M8: =IF(COUNT(F8:L8)=0,"",INDEX($F$6:$L$6,MATCH(IF($E8="Lower",MIN(F8:L8),MAX(F8:L8)),F8:L8,0))) | N8: =IF(OR(F8="",COUNT(F8:L8)=0),"",IF($E8="Lower",COUNTIF(F8:L8,"<"&F8),COUNTIF(F8:L8,">"&F8))+1) | O8: =COUNT(F8:L8) | P8: =IF(OR(F8="",COUNT(F8:L8)<2),"",IF($E8="Lower",IF(MIN(F8:L8)=0,"",(F8-MIN(F8:L8))/MIN(F8:L8)),IF(MAX(F8:L8)=0,"",(MAX(F8:L8)-F8)/MAX(F8:L8))))
A9: ='Metric Catalogue'!A7 | B9: ='Metric Catalogue'!B7 | C9: ='Metric Catalogue'!C7 | D9: ='Metric Catalogue'!D7 | E9: ='Metric Catalogue'!E7 | F9: =IFERROR(INDEX('1 Load & Network'!$L$5:$L$109,MATCH($A9&"|"&F$6&"|"&$C$3,'1 Load & Network'!$F$5:$F$109,0)),"") | G9: =IFERROR(INDEX('1 Load & Network'!$L$5:$L$109,MATCH($A9&"|"&G$6&"|"&$C$3,'1 Load & Network'!$F$5:$F$109,0)),"") | H9: =IFERROR(INDEX('1 Load & Network'!$L$5:$L$109,MATCH($A9&"|"&H$6&"|"&$C$3,'1 Load & Network'!$F$5:$F$109,0)),"") | I9: =IFERROR(INDEX('1 Load & Network'!$L$5:$L$109,MATCH($A9&"|"&I$6&"|"&$C$3,'1 Load & Network'!$F$5:$F$109,0)),"") | J9: =IFERROR(INDEX('1 Load & Network'!$L$5:$L$109,MATCH($A9&"|"&J$6&"|"&$C$3,'1 Load & Network'!$F$5:$F$109,0)),"") | K9: =IFERROR(INDEX('1 Load & Network'!$L$5:$L$109,MATCH($A9&"|"&K$6&"|"&$C$3,'1 Load & Network'!$F$5:$F$109,0)),"") | L9: =IFERROR(INDEX('1 Load & Network'!$L$5:$L$109,MATCH($A9&"|"&L$6&"|"&$C$3,'1 Load & Network'!$F$5:$F$109,0)),"") | M9: =IF(COUNT(F9:L9)=0,"",INDEX($F$6:$L$6,MATCH(IF($E9="Lower",MIN(F9:L9),MAX(F9:L9)),F9:L9,0))) | N9: =IF(OR(F9="",COUNT(F9:L9)=0),"",IF($E9="Lower",COUNTIF(F9:L9,"<"&F9),COUNTIF(F9:L9,">"&F9))+1) | O9: =COUNT(F9:L9) | P9: =IF(OR(F9="",COUNT(F9:L9)<2),"",IF($E9="Lower",IF(MIN(F9:L9)=0,"",(F9-MIN(F9:L9))/MIN(F9:L9)),IF(MAX(F9:L9)=0,"",(MAX(F9:L9)-F9)/MAX(F9:L9))))
A10: ='Metric Catalogue'!A8 | B10: ='Metric Catalogue'!B8 | C10: ='Metric Catalogue'!C8 | D10: ='Metric Catalogue'!D8 | E10: ='Metric Catalogue'!E8 | F10: =IFERROR(INDEX('1 Load & Network'!$L$5:$L$109,MATCH($A10&"|"&F$6&"|"&$C$3,'1 Load & Network'!$F$5:$F$109,0)),"") | G10: =IFERROR(INDEX('1 Load & Network'!$L$5:$L$109,MATCH($A10&"|"&G$6&"|"&$C$3,'1 Load & Network'!$F$5:$F$109,0)),"") | H10: =IFERROR(INDEX('1 Load & Network'!$L$5:$L$109,MATCH($A10&"|"&H$6&"|"&$C$3,'1 Load & Network'!$F$5:$F$109,0)),"") | I10: =IFERROR(INDEX('1 Load & Network'!$L$5:$L$109,MATCH($A10&"|"&I$6&"|"&$C$3,'1 Load & Network'!$F$5:$F$109,0)),"") | J10: =IFERROR(INDEX('1 Load & Network'!$L$5:$L$109,MATCH($A10&"|"&J$6&"|"&$C$3,'1 Load & Network'!$F$5:$F$109,0)),"") | K10: =IFERROR(INDEX('1 Load & Network'!$L$5:$L$109,MATCH($A10&"|"&K$6&"|"&$C$3,'1 Load & Network'!$F$5:$F$109,0)),"") | L10: =IFERROR(INDEX('1 Load & Network'!$L$5:$L$109,MATCH($A10&"|"&L$6&"|"&$C$3,'1 Load & Network'!$F$5:$F$109,0)),"") | M10: =IF(COUNT(F10:L10)=0,"",INDEX($F$6:$L$6,MATCH(IF($E10="Lower",MIN(F10:L10),MAX(F10:L10)),F10:L10,0))) | N10: =IF(OR(F10="",COUNT(F10:L10)=0),"",IF($E10="Lower",COUNTIF(F10:L10,"<"&F10),COUNTIF(F10:L10,">"&F10))+1) | O10: =COUNT(F10:L10) | P10: =IF(OR(F10="",COUNT(F10:L10)<2),"",IF($E10="Lower",IF(MIN(F10:L10)=0,"",(F10-MIN(F10:L10))/MIN(F10:L10)),IF(MAX(F10:L10)=0,"",(MAX(F10:L10)-F10)/MAX(F10:L10))))
A11: ='Metric Catalogue'!A9 | B11: ='Metric Catalogue'!B9 | C11: ='Metric Catalogue'!C9 | D11: ='Metric Catalogue'!D9 | E11: ='Metric Catalogue'!E9 | F11: =IFERROR(INDEX('1 Load & Network'!$L$5:$L$109,MATCH($A11&"|"&F$6&"|"&$C$3,'1 Load & Network'!$F$5:$F$109,0)),"") | G11: =IFERROR(INDEX('1 Load & Network'!$L$5:$L$109,MATCH($A11&"|"&G$6&"|"&$C$3,'1 Load & Network'!$F$5:$F$109,0)),"") | H11: =IFERROR(INDEX('1 Load & Network'!$L$5:$L$109,MATCH($A11&"|"&H$6&"|"&$C$3,'1 Load & Network'!$F$5:$F$109,0)),"") | I11: =IFERROR(INDEX('1 Load & Network'!$L$5:$L$109,MATCH($A11&"|"&I$6&"|"&$C$3,'1 Load & Network'!$F$5:$F$109,0)),"") | J11: =IFERROR(INDEX('1 Load & Network'!$L$5:$L$109,MATCH($A11&"|"&J$6&"|"&$C$3,'1 Load & Network'!$F$5:$F$109,0)),"") | K11: =IFERROR(INDEX('1 Load & Network'!$L$5:$L$109,MATCH($A11&"|"&K$6&"|"&$C$3,'1 Load & Network'!$F$5:$F$109,0)),"") | L11: =IFERROR(INDEX('1 Load & Network'!$L$5:$L$109,MATCH($A11&"|"&L$6&"|"&$C$3,'1 Load & Network'!$F$5:$F$109,0)),"") | M11: =IF(COUNT(F11:L11)=0,"",INDEX($F$6:$L$6,MATCH(IF($E11="Lower",MIN(F11:L11),MAX(F11:L11)),F11:L11,0))) | N11: =IF(OR(F11="",COUNT(F11:L11)=0),"",IF($E11="Lower",COUNTIF(F11:L11,"<"&F11),COUNTIF(F11:L11,">"&F11))+1) | O11: =COUNT(F11:L11) | P11: =IF(OR(F11="",COUNT(F11:L11)<2),"",IF($E11="Lower",IF(MIN(F11:L11)=0,"",(F11-MIN(F11:L11))/MIN(F11:L11)),IF(MAX(F11:L11)=0,"",(MAX(F11:L11)-F11)/MAX(F11:L11))))
A12: ='Metric Catalogue'!A10 | B12: ='Metric Catalogue'!B10 | C12: ='Metric Catalogue'!C10 | D12: ='Metric Catalogue'!D10 | E12: ='Metric Catalogue'!E10 | F12: =IFERROR(INDEX('1 Load & Network'!$L$5:$L$109,MATCH($A12&"|"&F$6&"|"&$C$3,'1 Load & Network'!$F$5:$F$109,0)),"") | G12: =IFERROR(INDEX('1 Load & Network'!$L$5:$L$109,MATCH($A12&"|"&G$6&"|"&$C$3,'1 Load & Network'!$F$5:$F$109,0)),"") | H12: =IFERROR(INDEX('1 Load & Network'!$L$5:$L$109,MATCH($A12&"|"&H$6&"|"&$C$3,'1 Load & Network'!$F$5:$F$109,0)),"") | I12: =IFERROR(INDEX('1 Load & Network'!$L$5:$L$109,MATCH($A12&"|"&I$6&"|"&$C$3,'1 Load & Network'!$F$5:$F$109,0)),"") | J12: =IFERROR(INDEX('1 Load & Network'!$L$5:$L$109,MATCH($A12&"|"&J$6&"|"&$C$3,'1 Load & Network'!$F$5:$F$109,0)),"") | K12: =IFERROR(INDEX('1 Load & Network'!$L$5:$L$109,MATCH($A12&"|"&K$6&"|"&$C$3,'1 Load & Network'!$F$5:$F$109,0)),"") | L12: =IFERROR(INDEX('1 Load & Network'!$L$5:$L$109,MATCH($A12&"|"&L$6&"|"&$C$3,'1 Load & Network'!$F$5:$F$109,0)),"") | M12: =IF(COUNT(F12:L12)=0,"",INDEX($F$6:$L$6,MATCH(IF($E12="Lower",MIN(F12:L12),MAX(F12:L12)),F12:L12,0))) | N12: =IF(OR(F12="",COUNT(F12:L12)=0),"",IF($E12="Lower",COUNTIF(F12:L12,"<"&F12),COUNTIF(F12:L12,">"&F12))+1) | O12: =COUNT(F12:L12) | P12: =IF(OR(F12="",COUNT(F12:L12)<2),"",IF($E12="Lower",IF(MIN(F12:L12)=0,"",(F12-MIN(F12:L12))/MIN(F12:L12)),IF(MAX(F12:L12)=0,"",(MAX(F12:L12)-F12)/MAX(F12:L12))))
A13: ='Metric Catalogue'!A11 | B13: ='Metric Catalogue'!B11 | C13: ='Metric Catalogue'!C11 | D13: ='Metric Catalogue'!D11 | E13: ='Metric Catalogue'!E11 | F13: =IFERROR(INDEX('1 Load & Network'!$L$5:$L$109,MATCH($A13&"|"&F$6&"|"&$C$3,'1 Load & Network'!$F$5:$F$109,0)),"") | G13: =IFERROR(INDEX('1 Load & Network'!$L$5:$L$109,MATCH($A13&"|"&G$6&"|"&$C$3,'1 Load & Network'!$F$5:$F$109,0)),"") | H13: =IFERROR(INDEX('1 Load & Network'!$L$5:$L$109,MATCH($A13&"|"&H$6&"|"&$C$3,'1 Load & Network'!$F$5:$F$109,0)),"") | I13: =IFERROR(INDEX('1 Load & Network'!$L$5:$L$109,MATCH($A13&"|"&I$6&"|"&$C$3,'1 Load & Network'!$F$5:$F$109,0)),"") | J13: =IFERROR(INDEX('1 Load & Network'!$L$5:$L$109,MATCH($A13&"|"&J$6&"|"&$C$3,'1 Load & Network'!$F$5:$F$109,0)),"") | K13: =IFERROR(INDEX('1 Load & Network'!$L$5:$L$109,MATCH($A13&"|"&K$6&"|"&$C$3,'1 Load & Network'!$F$5:$F$109,0)),"") | L13: =IFERROR(INDEX('1 Load & Network'!$L$5:$L$109,MATCH($A13&"|"&L$6&"|"&$C$3,'1 Load & Network'!$F$5:$F$109,0)),"") | M13: =IF(COUNT(F13:L13)=0,"",INDEX($F$6:$L$6,MATCH(IF($E13="Lower",MIN(F13:L13),MAX(F13:L13)),F13:L13,0))) | N13: =IF(OR(F13="",COUNT(F13:L13)=0),"",IF($E13="Lower",COUNTIF(F13:L13,"<"&F13),COUNTIF(F13:L13,">"&F13))+1) | O13: =COUNT(F13:L13) | P13: =IF(OR(F13="",COUNT(F13:L13)<2),"",IF($E13="Lower",IF(MIN(F13:L13)=0,"",(F13-MIN(F13:L13))/MIN(F13:L13)),IF(MAX(F13:L13)=0,"",(MAX(F13:L13)-F13)/MAX(F13:L13))))
A14: ='Metric Catalogue'!A12 | B14: ='Metric Catalogue'!B12 | C14: ='Metric Catalogue'!C12 | D14: ='Metric Catalogue'!D12 | E14: ='Metric Catalogue'!E12 | F14: =IFERROR(INDEX('1 Load & Network'!$L$5:$L$109,MATCH($A14&"|"&F$6&"|"&$C$3,'1 Load & Network'!$F$5:$F$109,0)),"") | G14: =IFERROR(INDEX('1 Load & Network'!$L$5:$L$109,MATCH($A14&"|"&G$6&"|"&$C$3,'1 Load & Network'!$F$5:$F$109,0)),"") | H14: =IFERROR(INDEX('1 Load & Network'!$L$5:$L$109,MATCH($A14&"|"&H$6&"|"&$C$3,'1 Load & Network'!$F$5:$F$109,0)),"") | I14: =IFERROR(INDEX('1 Load & Network'!$L$5:$L$109,MATCH($A14&"|"&I$6&"|"&$C$3,'1 Load & Network'!$F$5:$F$109,0)),"") | J14: =IFERROR(INDEX('1 Load & Network'!$L$5:$L$109,MATCH($A14&"|"&J$6&"|"&$C$3,'1 Load & Network'!$F$5:$F$109,0)),"") | K14: =IFERROR(INDEX('1 Load & Network'!$L$5:$L$109,MATCH($A14&"|"&K$6&"|"&$C$3,'1 Load & Network'!$F$5:$F$109,0)),"") | L14: =IFERROR(INDEX('1 Load & Network'!$L$5:$L$109,MATCH($A14&"|"&L$6&"|"&$C$3,'1 Load & Network'!$F$5:$F$109,0)),"") | M14: =IF(COUNT(F14:L14)=0,"",INDEX($F$6:$L$6,MATCH(IF($E14="Lower",MIN(F14:L14),MAX(F14:L14)),F14:L14,0))) | N14: =IF(OR(F14="",COUNT(F14:L14)=0),"",IF($E14="Lower",COUNTIF(F14:L14,"<"&F14),COUNTIF(F14:L14,">"&F14))+1) | O14: =COUNT(F14:L14) | P14: =IF(OR(F14="",COUNT(F14:L14)<2),"",IF($E14="Lower",IF(MIN(F14:L14)=0,"",(F14-MIN(F14:L14))/MIN(F14:L14)),IF(MAX(F14:L14)=0,"",(MAX(F14:L14)-F14)/MAX(F14:L14))))
A15: ='Metric Catalogue'!A13 | B15: ='Metric Catalogue'!B13 | C15: ='Metric Catalogue'!C13 | D15: ='Metric Catalogue'!D13 | E15: ='Metric Catalogue'!E13 | F15: =IFERROR(INDEX('1 Load & Network'!$L$5:$L$109,MATCH($A15&"|"&F$6&"|"&$C$3,'1 Load & Network'!$F$5:$F$109,0)),"") | G15: =IFERROR(INDEX('1 Load & Network'!$L$5:$L$109,MATCH($A15&"|"&G$6&"|"&$C$3,'1 Load & Network'!$F$5:$F$109,0)),"") | H15: =IFERROR(INDEX('1 Load & Network'!$L$5:$L$109,MATCH($A15&"|"&H$6&"|"&$C$3,'1 Load & Network'!$F$5:$F$109,0)),"") | I15: =IFERROR(INDEX('1 Load & Network'!$L$5:$L$109,MATCH($A15&"|"&I$6&"|"&$C$3,'1 Load & Network'!$F$5:$F$109,0)),"") | J15: =IFERROR(INDEX('1 Load & Network'!$L$5:$L$109,MATCH($A15&"|"&J$6&"|"&$C$3,'1 Load & Network'!$F$5:$F$109,0)),"") | K15: =IFERROR(INDEX('1 Load & Network'!$L$5:$L$109,MATCH($A15&"|"&K$6&"|"&$C$3,'1 Load & Network'!$F$5:$F$109,0)),"") | L15: =IFERROR(INDEX('1 Load & Network'!$L$5:$L$109,MATCH($A15&"|"&L$6&"|"&$C$3,'1 Load & Network'!$F$5:$F$109,0)),"") | M15: =IF(COUNT(F15:L15)=0,"",INDEX($F$6:$L$6,MATCH(IF($E15="Lower",MIN(F15:L15),MAX(F15:L15)),F15:L15,0))) | N15: =IF(OR(F15="",COUNT(F15:L15)=0),"",IF($E15="Lower",COUNTIF(F15:L15,"<"&F15),COUNTIF(F15:L15,">"&F15))+1) | O15: =COUNT(F15:L15) | P15: =IF(OR(F15="",COUNT(F15:L15)<2),"",IF($E15="Lower",IF(MIN(F15:L15)=0,"",(F15-MIN(F15:L15))/MIN(F15:L15)),IF(MAX(F15:L15)=0,"",(MAX(F15:L15)-F15)/MAX(F15:L15))))
A16: ='Metric Catalogue'!A14 | B16: ='Metric Catalogue'!B14 | C16: ='Metric Catalogue'!C14 | D16: ='Metric Catalogue'!D14 | E16: ='Metric Catalogue'!E14 | F16: =IFERROR(INDEX('1 Load & Network'!$L$5:$L$109,MATCH($A16&"|"&F$6&"|"&$C$3,'1 Load & Network'!$F$5:$F$109,0)),"") | G16: =IFERROR(INDEX('1 Load & Network'!$L$5:$L$109,MATCH($A16&"|"&G$6&"|"&$C$3,'1 Load & Network'!$F$5:$F$109,0)),"") | H16: =IFERROR(INDEX('1 Load & Network'!$L$5:$L$109,MATCH($A16&"|"&H$6&"|"&$C$3,'1 Load & Network'!$F$5:$F$109,0)),"") | I16: =IFERROR(INDEX('1 Load & Network'!$L$5:$L$109,MATCH($A16&"|"&I$6&"|"&$C$3,'1 Load & Network'!$F$5:$F$109,0)),"") | J16: =IFERROR(INDEX('1 Load & Network'!$L$5:$L$109,MATCH($A16&"|"&J$6&"|"&$C$3,'1 Load & Network'!$F$5:$F$109,0)),"") | K16: =IFERROR(INDEX('1 Load & Network'!$L$5:$L$109,MATCH($A16&"|"&K$6&"|"&$C$3,'1 Load & Network'!$F$5:$F$109,0)),"") | L16: =IFERROR(INDEX('1 Load & Network'!$L$5:$L$109,MATCH($A16&"|"&L$6&"|"&$C$3,'1 Load & Network'!$F$5:$F$109,0)),"") | M16: =IF(COUNT(F16:L16)=0,"",INDEX($F$6:$L$6,MATCH(IF($E16="Lower",MIN(F16:L16),MAX(F16:L16)),F16:L16,0))) | N16: =IF(OR(F16="",COUNT(F16:L16)=0),"",IF($E16="Lower",COUNTIF(F16:L16,"<"&F16),COUNTIF(F16:L16,">"&F16))+1) | O16: =COUNT(F16:L16) | P16: =IF(OR(F16="",COUNT(F16:L16)<2),"",IF($E16="Lower",IF(MIN(F16:L16)=0,"",(F16-MIN(F16:L16))/MIN(F16:L16)),IF(MAX(F16:L16)=0,"",(MAX(F16:L16)-F16)/MAX(F16:L16))))
A17: ='Metric Catalogue'!A15 | B17: ='Metric Catalogue'!B15 | C17: ='Metric Catalogue'!C15 | D17: ='Metric Catalogue'!D15 | E17: ='Metric Catalogue'!E15 | F17: =IFERROR(INDEX('1 Load & Network'!$L$5:$L$109,MATCH($A17&"|"&F$6&"|"&$C$3,'1 Load & Network'!$F$5:$F$109,0)),"") | G17: =IFERROR(INDEX('1 Load & Network'!$L$5:$L$109,MATCH($A17&"|"&G$6&"|"&$C$3,'1 Load & Network'!$F$5:$F$109,0)),"") | H17: =IFERROR(INDEX('1 Load & Network'!$L$5:$L$109,MATCH($A17&"|"&H$6&"|"&$C$3,'1 Load & Network'!$F$5:$F$109,0)),"") | I17: =IFERROR(INDEX('1 Load & Network'!$L$5:$L$109,MATCH($A17&"|"&I$6&"|"&$C$3,'1 Load & Network'!$F$5:$F$109,0)),"") | J17: =IFERROR(INDEX('1 Load & Network'!$L$5:$L$109,MATCH($A17&"|"&J$6&"|"&$C$3,'1 Load & Network'!$F$5:$F$109,0)),"") | K17: =IFERROR(INDEX('1 Load & Network'!$L$5:$L$109,MATCH($A17&"|"&K$6&"|"&$C$3,'1 Load & Network'!$F$5:$F$109,0)),"") | L17: =IFERROR(INDEX('1 Load & Network'!$L$5:$L$109,MATCH($A17&"|"&L$6&"|"&$C$3,'1 Load & Network'!$F$5:$F$109,0)),"") | M17: =IF(COUNT(F17:L17)=0,"",INDEX($F$6:$L$6,MATCH(IF($E17="Lower",MIN(F17:L17),MAX(F17:L17)),F17:L17,0))) | N17: =IF(OR(F17="",COUNT(F17:L17)=0),"",IF($E17="Lower",COUNTIF(F17:L17,"<"&F17),COUNTIF(F17:L17,">"&F17))+1) | O17: =COUNT(F17:L17) | P17: =IF(OR(F17="",COUNT(F17:L17)<2),"",IF($E17="Lower",IF(MIN(F17:L17)=0,"",(F17-MIN(F17:L17))/MIN(F17:L17)),IF(MAX(F17:L17)=0,"",(MAX(F17:L17)-F17)/MAX(F17:L17))))
A18: ='Metric Catalogue'!A16 | B18: ='Metric Catalogue'!B16 | C18: ='Metric Catalogue'!C16 | D18: ='Metric Catalogue'!D16 | E18: ='Metric Catalogue'!E16 | F18: =IFERROR(INDEX('1 Load & Network'!$L$5:$L$109,MATCH($A18&"|"&F$6&"|"&$C$3,'1 Load & Network'!$F$5:$F$109,0)),"") | G18: =IFERROR(INDEX('1 Load & Network'!$L$5:$L$109,MATCH($A18&"|"&G$6&"|"&$C$3,'1 Load & Network'!$F$5:$F$109,0)),"") | H18: =IFERROR(INDEX('1 Load & Network'!$L$5:$L$109,MATCH($A18&"|"&H$6&"|"&$C$3,'1 Load & Network'!$F$5:$F$109,0)),"") | I18: =IFERROR(INDEX('1 Load & Network'!$L$5:$L$109,MATCH($A18&"|"&I$6&"|"&$C$3,'1 Load & Network'!$F$5:$F$109,0)),"") | J18: =IFERROR(INDEX('1 Load & Network'!$L$5:$L$109,MATCH($A18&"|"&J$6&"|"&$C$3,'1 Load & Network'!$F$5:$F$109,0)),"") | K18: =IFERROR(INDEX('1 Load & Network'!$L$5:$L$109,MATCH($A18&"|"&K$6&"|"&$C$3,'1 Load & Network'!$F$5:$F$109,0)),"") | L18: =IFERROR(INDEX('1 Load & Network'!$L$5:$L$109,MATCH($A18&"|"&L$6&"|"&$C$3,'1 Load & Network'!$F$5:$F$109,0)),"") | M18: =IF(COUNT(F18:L18)=0,"",INDEX($F$6:$L$6,MATCH(IF($E18="Lower",MIN(F18:L18),MAX(F18:L18)),F18:L18,0))) | N18: =IF(OR(F18="",COUNT(F18:L18)=0),"",IF($E18="Lower",COUNTIF(F18:L18,"<"&F18),COUNTIF(F18:L18,">"&F18))+1) | O18: =COUNT(F18:L18) | P18: =IF(OR(F18="",COUNT(F18:L18)<2),"",IF($E18="Lower",IF(MIN(F18:L18)=0,"",(F18-MIN(F18:L18))/MIN(F18:L18)),IF(MAX(F18:L18)=0,"",(MAX(F18:L18)-F18)/MAX(F18:L18))))
... A21: ='Metric Catalogue'!A19 | B21: ='Metric Catalogue'!B19 | C21: ='Metric Catalogue'!C19 | D21: ='Metric Catalogue'!D19 | E21: ='Metric Catalogue'!E19 | F21: =IFERROR(INDEX('1 Load & Network'!$L$5:$L$109,MATCH($A21&"|"&F$6&"|"&$C$3,'1 Load & Network'!$F$5:$F$109,0)),"") | G21: =IFERROR(INDEX('1 Load & Network'!$L$5:$L$109,MATCH($A21&"|"&G$6&"|"&$C$3,'1 Load & Network'!$F$5:$F$109,0)),"") | H21: =IFERROR(INDEX('1 Load & Network'!$L$5:$L$109,MATCH($A21&"|"&H$6&"|"&$C$3,'1 Load & Network'!$F$5:$F$109,0)),"") | I21: =IFERROR(INDEX('1 Load & Network'!$L$5:$L$109,MATCH($A21&"|"&I$6&"|"&$C$3,'1 Load & Network'!$F$5:$F$109,0)),"") | J21: =IFERROR(INDEX('1 Load & Network'!$L$5:$L$109,MATCH($A21&"|"&J$6&"|"&$C$3,'1 Load & Network'!$F$5:$F$109,0)),"") | K21: =IFERROR(INDEX('1 Load & Network'!$L$5:$L$109,MATCH($A21&"|"&K$6&"|"&$C$3,'1 Load & Network'!$F$5:$F$109,0)),"") | L21: =IFERROR(INDEX('1 Load & Network'!$L$5:$L$109,MATCH($A21&"|"&L$6&"|"&$C$3,'1 Load & Network'!$F$5:$F$109,0)),"") | M21: =IF(COUNT(F21:L21)=0,"",INDEX($F$6:$L$6,MATCH(IF($E21="Lower",MIN(F21:L21),MAX(F21:L21)),F21:L21,0))) | N21: =IF(OR(F21="",COUNT(F21:L21)=0),"",IF($E21="Lower",COUNTIF(F21:L21,"<"&F21),COUNTIF(F21:L21,">"&F21))+1) | O21: =COUNT(F21:L21) | P21: =IF(OR(F21="",COUNT(F21:L21)<2),"",IF($E21="Lower",IF(MIN(F21:L21)=0,"",(F21-MIN(F21:L21))/MIN(F21:L21)),IF(MAX(F21:L21)=0,"",(MAX(F21:L21)-F21)/MAX(F21:L21))))
A22: ='Metric Catalogue'!A20 | B22: ='Metric Catalogue'!B20 | C22: ='Metric Catalogue'!C20 | D22: ='Metric Catalogue'!D20 | E22: ='Metric Catalogue'!E20 | F22: =IFERROR(INDEX('2 Scroll FPS'!$L$5:$L$53,MATCH($A22&"|"&F$6&"|"&$C$3,'2 Scroll FPS'!$F$5:$F$53,0)),"") | G22: =IFERROR(INDEX('2 Scroll FPS'!$L$5:$L$53,MATCH($A22&"|"&G$6&"|"&$C$3,'2 Scroll FPS'!$F$5:$F$53,0)),"") | H22: =IFERROR(INDEX('2 Scroll FPS'!$L$5:$L$53,MATCH($A22&"|"&H$6&"|"&$C$3,'2 Scroll FPS'!$F$5:$F$53,0)),"") | I22: =IFERROR(INDEX('2 Scroll FPS'!$L$5:$L$53,MATCH($A22&"|"&I$6&"|"&$C$3,'2 Scroll FPS'!$F$5:$F$53,0)),"") | J22: =IFERROR(INDEX('2 Scroll FPS'!$L$5:$L$53,MATCH($A22&"|"&J$6&"|"&$C$3,'2 Scroll FPS'!$F$5:$F$53,0)),"") | K22: =IFERROR(INDEX('2 Scroll FPS'!$L$5:$L$53,MATCH($A22&"|"&K$6&"|"&$C$3,'2 Scroll FPS'!$F$5:$F$53,0)),"") | L22: =IFERROR(INDEX('2 Scroll FPS'!$L$5:$L$53,MATCH($A22&"|"&L$6&"|"&$C$3,'2 Scroll FPS'!$F$5:$F$53,0)),"") | M22: =IF(COUNT(F22:L22)=0,"",INDEX($F$6:$L$6,MATCH(IF($E22="Lower",MIN(F22:L22),MAX(F22:L22)),F22:L22,0))) | N22: =IF(OR(F22="",COUNT(F22:L22)=0),"",IF($E22="Lower",COUNTIF(F22:L22,"<"&F22),COUNTIF(F22:L22,">"&F22))+1) | O22: =COUNT(F22:L22) | P22: =IF(OR(F22="",COUNT(F22:L22)<2),"",IF($E22="Lower",IF(MIN(F22:L22)=0,"",(F22-MIN(F22:L22))/MIN(F22:L22)),IF(MAX(F22:L22)=0,"",(MAX(F22:L22)-F22)/MAX(F22:L22))))
A23: ='Metric Catalogue'!A21 | B23: ='Metric Catalogue'!B21 | C23: ='Metric Catalogue'!C21 | D23: ='Metric Catalogue'!D21 | E23: ='Metric Catalogue'!E21 | F23: =IFERROR(INDEX('2 Scroll FPS'!$L$5:$L$53,MATCH($A23&"|"&F$6&"|"&$C$3,'2 Scroll FPS'!$F$5:$F$53,0)),"") | G23: =IFERROR(INDEX('2 Scroll FPS'!$L$5:$L$53,MATCH($A23&"|"&G$6&"|"&$C$3,'2 Scroll FPS'!$F$5:$F$53,0)),"") | H23: =IFERROR(INDEX('2 Scroll FPS'!$L$5:$L$53,MATCH($A23&"|"&H$6&"|"&$C$3,'2 Scroll FPS'!$F$5:$F$53,0)),"") | I23: =IFERROR(INDEX('2 Scroll FPS'!$L$5:$L$53,MATCH($A23&"|"&I$6&"|"&$C$3,'2 Scroll FPS'!$F$5:$F$53,0)),"") | J23: =IFERROR(INDEX('2 Scroll FPS'!$L$5:$L$53,MATCH($A23&"|"&J$6&"|"&$C$3,'2 Scroll FPS'!$F$5:$F$53,0)),"") | K23: =IFERROR(INDEX('2 Scroll FPS'!$L$5:$L$53,MATCH($A23&"|"&K$6&"|"&$C$3,'2 Scroll FPS'!$F$5:$F$53,0)),"") | L23: =IFERROR(INDEX('2 Scroll FPS'!$L$5:$L$53,MATCH($A23&"|"&L$6&"|"&$C$3,'2 Scroll FPS'!$F$5:$F$53,0)),"") | M23: =IF(COUNT(F23:L23)=0,"",INDEX($F$6:$L$6,MATCH(IF($E23="Lower",MIN(F23:L23),MAX(F23:L23)),F23:L23,0))) | N23: =IF(OR(F23="",COUNT(F23:L23)=0),"",IF($E23="Lower",COUNTIF(F23:L23,"<"&F23),COUNTIF(F23:L23,">"&F23))+1) | O23: =COUNT(F23:L23) | P23: =IF(OR(F23="",COUNT(F23:L23)<2),"",IF($E23="Lower",IF(MIN(F23:L23)=0,"",(F23-MIN(F23:L23))/MIN(F23:L23)),IF(MAX(F23:L23)=0,"",(MAX(F23:L23)-F23)/MAX(F23:L23))))
A24: ='Metric Catalogue'!A22 | B24: ='Metric Catalogue'!B22 | C24: ='Metric Catalogue'!C22 | D24: ='Metric Catalogue'!D22 | E24: ='Metric Catalogue'!E22 | F24: =IFERROR(INDEX('2 Scroll FPS'!$L$5:$L$53,MATCH($A24&"|"&F$6&"|"&$C$3,'2 Scroll FPS'!$F$5:$F$53,0)),"") | G24: =IFERROR(INDEX('2 Scroll FPS'!$L$5:$L$53,MATCH($A24&"|"&G$6&"|"&$C$3,'2 Scroll FPS'!$F$5:$F$53,0)),"") | H24: =IFERROR(INDEX('2 Scroll FPS'!$L$5:$L$53,MATCH($A24&"|"&H$6&"|"&$C$3,'2 Scroll FPS'!$F$5:$F$53,0)),"") | I24: =IFERROR(INDEX('2 Scroll FPS'!$L$5:$L$53,MATCH($A24&"|"&I$6&"|"&$C$3,'2 Scroll FPS'!$F$5:$F$53,0)),"") | J24: =IFERROR(INDEX('2 Scroll FPS'!$L$5:$L$53,MATCH($A24&"|"&J$6&"|"&$C$3,'2 Scroll FPS'!$F$5:$F$53,0)),"") | K24: =IFERROR(INDEX('2 Scroll FPS'!$L$5:$L$53,MATCH($A24&"|"&K$6&"|"&$C$3,'2 Scroll FPS'!$F$5:$F$53,0)),"") | L24: =IFERROR(INDEX('2 Scroll FPS'!$L$5:$L$53,MATCH($A24&"|"&L$6&"|"&$C$3,'2 Scroll FPS'!$F$5:$F$53,0)),"") | M24: =IF(COUNT(F24:L24)=0,"",INDEX($F$6:$L$6,MATCH(IF($E24="Lower",MIN(F24:L24),MAX(F24:L24)),F24:L24,0))) | N24: =IF(OR(F24="",COUNT(F24:L24)=0),"",IF($E24="Lower",COUNTIF(F24:L24,"<"&F24),COUNTIF(F24:L24,">"&F24))+1) | O24: =COUNT(F24:L24) | P24: =IF(OR(F24="",COUNT(F24:L24)<2),"",IF($E24="Lower",IF(MIN(F24:L24)=0,"",(F24-MIN(F24:L24))/MIN(F24:L24)),IF(MAX(F24:L24)=0,"",(MAX(F24:L24)-F24)/MAX(F24:L24))))
A25: ='Metric Catalogue'!A23 | B25: ='Metric Catalogue'!B23 | C25: ='Metric Catalogue'!C23 | D25: ='Metric Catalogue'!D23 | E25: ='Metric Catalogue'!E23 | F25: =IFERROR(INDEX('2 Scroll FPS'!$L$5:$L$53,MATCH($A25&"|"&F$6&"|"&$C$3,'2 Scroll FPS'!$F$5:$F$53,0)),"") | G25: =IFERROR(INDEX('2 Scroll FPS'!$L$5:$L$53,MATCH($A25&"|"&G$6&"|"&$C$3,'2 Scroll FPS'!$F$5:$F$53,0)),"") | H25: =IFERROR(INDEX('2 Scroll FPS'!$L$5:$L$53,MATCH($A25&"|"&H$6&"|"&$C$3,'2 Scroll FPS'!$F$5:$F$53,0)),"") | I25: =IFERROR(INDEX('2 Scroll FPS'!$L$5:$L$53,MATCH($A25&"|"&I$6&"|"&$C$3,'2 Scroll FPS'!$F$5:$F$53,0)),"") | J25: =IFERROR(INDEX('2 Scroll FPS'!$L$5:$L$53,MATCH($A25&"|"&J$6&"|"&$C$3,'2 Scroll FPS'!$F$5:$F$53,0)),"") | K25: =IFERROR(INDEX('2 Scroll FPS'!$L$5:$L$53,MATCH($A25&"|"&K$6&"|"&$C$3,'2 Scroll FPS'!$F$5:$F$53,0)),"") | L25: =IFERROR(INDEX('2 Scroll FPS'!$L$5:$L$53,MATCH($A25&"|"&L$6&"|"&$C$3,'2 Scroll FPS'!$F$5:$F$53,0)),"") | M25: =IF(COUNT(F25:L25)=0,"",INDEX($F$6:$L$6,MATCH(IF($E25="Lower",MIN(F25:L25),MAX(F25:L25)),F25:L25,0))) | N25: =IF(OR(F25="",COUNT(F25:L25)=0),"",IF($E25="Lower",COUNTIF(F25:L25,"<"&F25),COUNTIF(F25:L25,">"&F25))+1) | O25: =COUNT(F25:L25) | P25: =IF(OR(F25="",COUNT(F25:L25)<2),"",IF($E25="Lower",IF(MIN(F25:L25)=0,"",(F25-MIN(F25:L25))/MIN(F25:L25)),IF(MAX(F25:L25)=0,"",(MAX(F25:L25)-F25)/MAX(F25:L25))))
A26: ='Metric Catalogue'!A24 | B26: ='Metric Catalogue'!B24 | C26: ='Metric Catalogue'!C24 | D26: ='Metric Catalogue'!D24 | E26: ='Metric Catalogue'!E24 | F26: =IFERROR(INDEX('2 Scroll FPS'!$L$5:$L$53,MATCH($A26&"|"&F$6&"|"&$C$3,'2 Scroll FPS'!$F$5:$F$53,0)),"") | G26: =IFERROR(INDEX('2 Scroll FPS'!$L$5:$L$53,MATCH($A26&"|"&G$6&"|"&$C$3,'2 Scroll FPS'!$F$5:$F$53,0)),"") | H26: =IFERROR(INDEX('2 Scroll FPS'!$L$5:$L$53,MATCH($A26&"|"&H$6&"|"&$C$3,'2 Scroll FPS'!$F$5:$F$53,0)),"") | I26: =IFERROR(INDEX('2 Scroll FPS'!$L$5:$L$53,MATCH($A26&"|"&I$6&"|"&$C$3,'2 Scroll FPS'!$F$5:$F$53,0)),"") | J26: =IFERROR(INDEX('2 Scroll FPS'!$L$5:$L$53,MATCH($A26&"|"&J$6&"|"&$C$3,'2 Scroll FPS'!$F$5:$F$53,0)),"") | K26: =IFERROR(INDEX('2 Scroll FPS'!$L$5:$L$53,MATCH($A26&"|"&K$6&"|"&$C$3,'2 Scroll FPS'!$F$5:$F$53,0)),"") | L26: =IFERROR(INDEX('2 Scroll FPS'!$L$5:$L$53,MATCH($A26&"|"&L$6&"|"&$C$3,'2 Scroll FPS'!$F$5:$F$53,0)),"") | M26: =IF(COUNT(F26:L26)=0,"",INDEX($F$6:$L$6,MATCH(IF($E26="Lower",MIN(F26:L26),MAX(F26:L26)),F26:L26,0))) | N26: =IF(OR(F26="",COUNT(F26:L26)=0),"",IF($E26="Lower",COUNTIF(F26:L26,"<"&F26),COUNTIF(F26:L26,">"&F26))+1) | O26: =COUNT(F26:L26) | P26: =IF(OR(F26="",COUNT(F26:L26)<2),"",IF($E26="Lower",IF(MIN(F26:L26)=0,"",(F26-MIN(F26:L26))/MIN(F26:L26)),IF(MAX(F26:L26)=0,"",(MAX(F26:L26)-F26)/MAX(F26:L26))))
A27: ='Metric Catalogue'!A25 | B27: ='Metric Catalogue'!B25 | C27: ='Metric Catalogue'!C25 | D27: ='Metric Catalogue'!D25 | E27: ='Metric Catalogue'!E25 | F27: =IFERROR(INDEX('2 Scroll FPS'!$L$5:$L$53,MATCH($A27&"|"&F$6&"|"&$C$3,'2 Scroll FPS'!$F$5:$F$53,0)),"") | G27: =IFERROR(INDEX('2 Scroll FPS'!$L$5:$L$53,MATCH($A27&"|"&G$6&"|"&$C$3,'2 Scroll FPS'!$F$5:$F$53,0)),"") | H27: =IFERROR(INDEX('2 Scroll FPS'!$L$5:$L$53,MATCH($A27&"|"&H$6&"|"&$C$3,'2 Scroll FPS'!$F$5:$F$53,0)),"") | I27: =IFERROR(INDEX('2 Scroll FPS'!$L$5:$L$53,MATCH($A27&"|"&I$6&"|"&$C$3,'2 Scroll FPS'!$F$5:$F$53,0)),"") | J27: =IFERROR(INDEX('2 Scroll FPS'!$L$5:$L$53,MATCH($A27&"|"&J$6&"|"&$C$3,'2 Scroll FPS'!$F$5:$F$53,0)),"") | K27: =IFERROR(INDEX('2 Scroll FPS'!$L$5:$L$53,MATCH($A27&"|"&K$6&"|"&$C$3,'2 Scroll FPS'!$F$5:$F$53,0)),"") | L27: =IFERROR(INDEX('2 Scroll FPS'!$L$5:$L$53,MATCH($A27&"|"&L$6&"|"&$C$3,'2 Scroll FPS'!$F$5:$F$53,0)),"") | M27: =IF(COUNT(F27:L27)=0,"",INDEX($F$6:$L$6,MATCH(IF($E27="Lower",MIN(F27:L27),MAX(F27:L27)),F27:L27,0))) | N27: =IF(OR(F27="",COUNT(F27:L27)=0),"",IF($E27="Lower",COUNTIF(F27:L27,"<"&F27),COUNTIF(F27:L27,">"&F27))+1) | O27: =COUNT(F27:L27) | P27: =IF(OR(F27="",COUNT(F27:L27)<2),"",IF($E27="Lower",IF(MIN(F27:L27)=0,"",(F27-MIN(F27:L27))/MIN(F27:L27)),IF(MAX(F27:L27)=0,"",(MAX(F27:L27)-F27)/MAX(F27:L27))))
A28: ='Metric Catalogue'!A26 | B28: ='Metric Catalogue'!B26 | C28: ='Metric Catalogue'!C26 | D28: ='Metric Catalogue'!D26 | E28: ='Metric Catalogue'!E26 | F28: =IFERROR(INDEX('2 Scroll FPS'!$L$5:$L$53,MATCH($A28&"|"&F$6&"|"&$C$3,'2 Scroll FPS'!$F$5:$F$53,0)),"") | G28: =IFERROR(INDEX('2 Scroll FPS'!$L$5:$L$53,MATCH($A28&"|"&G$6&"|"&$C$3,'2 Scroll FPS'!$F$5:$F$53,0)),"") | H28: =IFERROR(INDEX('2 Scroll FPS'!$L$5:$L$53,MATCH($A28&"|"&H$6&"|"&$C$3,'2 Scroll FPS'!$F$5:$F$53,0)),"") | I28: =IFERROR(INDEX('2 Scroll FPS'!$L$5:$L$53,MATCH($A28&"|"&I$6&"|"&$C$3,'2 Scroll FPS'!$F$5:$F$53,0)),"") | J28: =IFERROR(INDEX('2 Scroll FPS'!$L$5:$L$53,MATCH($A28&"|"&J$6&"|"&$C$3,'2 Scroll FPS'!$F$5:$F$53,0)),"") | K28: =IFERROR(INDEX('2 Scroll FPS'!$L$5:$L$53,MATCH($A28&"|"&K$6&"|"&$C$3,'2 Scroll FPS'!$F$5:$F$53,0)),"") | L28: =IFERROR(INDEX('2 Scroll FPS'!$L$5:$L$53,MATCH($A28&"|"&L$6&"|"&$C$3,'2 Scroll FPS'!$F$5:$F$53,0)),"") | M28: =IF(COUNT(F28:L28)=0,"",INDEX($F$6:$L$6,MATCH(IF($E28="Lower",MIN(F28:L28),MAX(F28:L28)),F28:L28,0))) | N28: =IF(OR(F28="",COUNT(F28:L28)=0),"",IF($E28="Lower",COUNTIF(F28:L28,"<"&F28),COUNTIF(F28:L28,">"&F28))+1) | O28: =COUNT(F28:L28) | P28: =IF(OR(F28="",COUNT(F28:L28)<2),"",IF($E28="Lower",IF(MIN(F28:L28)=0,"",(F28-MIN(F28:L28))/MIN(F28:L28)),IF(MAX(F28:L28)=0,"",(MAX(F28:L28)-F28)/MAX(F28:L28))))
A29: ='Metric Catalogue'!A27 | B29: ='Metric Catalogue'!B27 | C29: ='Metric Catalogue'!C27 | D29: ='Metric Catalogue'!D27 | E29: ='Metric Catalogue'!E27 | F29: =IFERROR(INDEX('3 Screen Updates'!$L$5:$L$39,MATCH($A29&"|"&F$6&"|"&$C$3,'3 Screen Updates'!$F$5:$F$39,0)),"") | G29: =IFERROR(INDEX('3 Screen Updates'!$L$5:$L$39,MATCH($A29&"|"&G$6&"|"&$C$3,'3 Screen Updates'!$F$5:$F$39,0)),"") | H29: =IFERROR(INDEX('3 Screen Updates'!$L$5:$L$39,MATCH($A29&"|"&H$6&"|"&$C$3,'3 Screen Updates'!$F$5:$F$39,0)),"") | I29: =IFERROR(INDEX('3 Screen Updates'!$L$5:$L$39,MATCH($A29&"|"&I$6&"|"&$C$3,'3 Screen Updates'!$F$5:$F$39,0)),"") | J29: =IFERROR(INDEX('3 Screen Updates'!$L$5:$L$39,MATCH($A29&"|"&J$6&"|"&$C$3,'3 Screen Updates'!$F$5:$F$39,0)),"") | K29: =IFERROR(INDEX('3 Screen Updates'!$L$5:$L$39,MATCH($A29&"|"&K$6&"|"&$C$3,'3 Screen Updates'!$F$5:$F$39,0)),"") | L29: =IFERROR(INDEX('3 Screen Updates'!$L$5:$L$39,MATCH($A29&"|"&L$6&"|"&$C$3,'3 Screen Updates'!$F$5:$F$39,0)),"") | M29: =IF(COUNT(F29:L29)=0,"",INDEX($F$6:$L$6,MATCH(IF($E29="Lower",MIN(F29:L29),MAX(F29:L29)),F29:L29,0))) | N29: =IF(OR(F29="",COUNT(F29:L29)=0),"",IF($E29="Lower",COUNTIF(F29:L29,"<"&F29),COUNTIF(F29:L29,">"&F29))+1) | O29: =COUNT(F29:L29) | P29: =IF(OR(F29="",COUNT(F29:L29)<2),"",IF($E29="Lower",IF(MIN(F29:L29)=0,"",(F29-MIN(F29:L29))/MIN(F29:L29)),IF(MAX(F29:L29)=0,"",(MAX(F29:L29)-F29)/MAX(F29:L29))))
A30: ='Metric Catalogue'!A28 | B30: ='Metric Catalogue'!B28 | C30: ='Metric Catalogue'!C28 | D30: ='Metric Catalogue'!D28 | E30: ='Metric Catalogue'!E28 | F30: =IFERROR(INDEX('3 Screen Updates'!$L$5:$L$39,MATCH($A30&"|"&F$6&"|"&$C$3,'3 Screen Updates'!$F$5:$F$39,0)),"") | G30: =IFERROR(INDEX('3 Screen Updates'!$L$5:$L$39,MATCH($A30&"|"&G$6&"|"&$C$3,'3 Screen Updates'!$F$5:$F$39,0)),"") | H30: =IFERROR(INDEX('3 Screen Updates'!$L$5:$L$39,MATCH($A30&"|"&H$6&"|"&$C$3,'3 Screen Updates'!$F$5:$F$39,0)),"") | I30: =IFERROR(INDEX('3 Screen Updates'!$L$5:$L$39,MATCH($A30&"|"&I$6&"|"&$C$3,'3 Screen Updates'!$F$5:$F$39,0)),"") | J30: =IFERROR(INDEX('3 Screen Updates'!$L$5:$L$39,MATCH($A30&"|"&J$6&"|"&$C$3,'3 Screen Updates'!$F$5:$F$39,0)),"") | K30: =IFERROR(INDEX('3 Screen Updates'!$L$5:$L$39,MATCH($A30&"|"&K$6&"|"&$C$3,'3 Screen Updates'!$F$5:$F$39,0)),"") | L30: =IFERROR(INDEX('3 Screen Updates'!$L$5:$L$39,MATCH($A30&"|"&L$6&"|"&$C$3,'3 Screen Updates'!$F$5:$F$39,0)),"") | M30: =IF(COUNT(F30:L30)=0,"",INDEX($F$6:$L$6,MATCH(IF($E30="Lower",MIN(F30:L30),MAX(F30:L30)),F30:L30,0))) | N30: =IF(OR(F30="",COUNT(F30:L30)=0),"",IF($E30="Lower",COUNTIF(F30:L30,"<"&F30),COUNTIF(F30:L30,">"&F30))+1) | O30: =COUNT(F30:L30) | P30: =IF(OR(F30="",COUNT(F30:L30)<2),"",IF($E30="Lower",IF(MIN(F30:L30)=0,"",(F30-MIN(F30:L30))/MIN(F30:L30)),IF(MAX(F30:L30)=0,"",(MAX(F30:L30)-F30)/MAX(F30:L30))))
A31: ='Metric Catalogue'!A29 | B31: ='Metric Catalogue'!B29 | C31: ='Metric Catalogue'!C29 | D31: ='Metric Catalogue'!D29 | E31: ='Metric Catalogue'!E29 | F31: =IFERROR(INDEX('3 Screen Updates'!$L$5:$L$39,MATCH($A31&"|"&F$6&"|"&$C$3,'3 Screen Updates'!$F$5:$F$39,0)),"") | G31: =IFERROR(INDEX('3 Screen Updates'!$L$5:$L$39,MATCH($A31&"|"&G$6&"|"&$C$3,'3 Screen Updates'!$F$5:$F$39,0)),"") | H31: =IFERROR(INDEX('3 Screen Updates'!$L$5:$L$39,MATCH($A31&"|"&H$6&"|"&$C$3,'3 Screen Updates'!$F$5:$F$39,0)),"") | I31: =IFERROR(INDEX('3 Screen Updates'!$L$5:$L$39,MATCH($A31&"|"&I$6&"|"&$C$3,'3 Screen Updates'!$F$5:$F$39,0)),"") | J31: =IFERROR(INDEX('3 Screen Updates'!$L$5:$L$39,MATCH($A31&"|"&J$6&"|"&$C$3,'3 Screen Updates'!$F$5:$F$39,0)),"") | K31: =IFERROR(INDEX('3 Screen Updates'!$L$5:$L$39,MATCH($A31&"|"&K$6&"|"&$C$3,'3 Screen Updates'!$F$5:$F$39,0)),"") | L31: =IFERROR(INDEX('3 Screen Updates'!$L$5:$L$39,MATCH($A31&"|"&L$6&"|"&$C$3,'3 Screen Updates'!$F$5:$F$39,0)),"") | M31: =IF(COUNT(F31:L31)=0,"",INDEX($F$6:$L$6,MATCH(IF($E31="Lower",MIN(F31:L31),MAX(F31:L31)),F31:L31,0))) | N31: =IF(OR(F31="",COUNT(F31:L31)=0),"",IF($E31="Lower",COUNTIF(F31:L31,"<"&F31),COUNTIF(F31:L31,">"&F31))+1) | O31: =COUNT(F31:L31) | P31: =IF(OR(F31="",COUNT(F31:L31)<2),"",IF($E31="Lower",IF(MIN(F31:L31)=0,"",(F31-MIN(F31:L31))/MIN(F31:L31)),IF(MAX(F31:L31)=0,"",(MAX(F31:L31)-F31)/MAX(F31:L31))))
A32: ='Metric Catalogue'!A30 | B32: ='Metric Catalogue'!B30 | C32: ='Metric Catalogue'!C30 | D32: ='Metric Catalogue'!D30 | E32: ='Metric Catalogue'!E30 | F32: =IFERROR(INDEX('3 Screen Updates'!$L$5:$L$39,MATCH($A32&"|"&F$6&"|"&$C$3,'3 Screen Updates'!$F$5:$F$39,0)),"") | G32: =IFERROR(INDEX('3 Screen Updates'!$L$5:$L$39,MATCH($A32&"|"&G$6&"|"&$C$3,'3 Screen Updates'!$F$5:$F$39,0)),"") | H32: =IFERROR(INDEX('3 Screen Updates'!$L$5:$L$39,MATCH($A32&"|"&H$6&"|"&$C$3,'3 Screen Updates'!$F$5:$F$39,0)),"") | I32: =IFERROR(INDEX('3 Screen Updates'!$L$5:$L$39,MATCH($A32&"|"&I$6&"|"&$C$3,'3 Screen Updates'!$F$5:$F$39,0)),"") | J32: =IFERROR(INDEX('3 Screen Updates'!$L$5:$L$39,MATCH($A32&"|"&J$6&"|"&$C$3,'3 Screen Updates'!$F$5:$F$39,0)),"") | K32: =IFERROR(INDEX('3 Screen Updates'!$L$5:$L$39,MATCH($A32&"|"&K$6&"|"&$C$3,'3 Screen Updates'!$F$5:$F$39,0)),"") | L32: =IFERROR(INDEX('3 Screen Updates'!$L$5:$L$39,MATCH($A32&"|"&L$6&"|"&$C$3,'3 Screen Updates'!$F$5:$F$39,0)),"") | M32: =IF(COUNT(F32:L32)=0,"",INDEX($F$6:$L$6,MATCH(IF($E32="Lower",MIN(F32:L32),MAX(F32:L32)),F32:L32,0))) | N32: =IF(OR(F32="",COUNT(F32:L32)=0),"",IF($E32="Lower",COUNTIF(F32:L32,"<"&F32),COUNTIF(F32:L32,">"&F32))+1) | O32: =COUNT(F32:L32) | P32: =IF(OR(F32="",COUNT(F32:L32)<2),"",IF($E32="Lower",IF(MIN(F32:L32)=0,"",(F32-MIN(F32:L32))/MIN(F32:L32)),IF(MAX(F32:L32)=0,"",(MAX(F32:L32)-F32)/MAX(F32:L32))))
A33: ='Metric Catalogue'!A31 | B33: ='Metric Catalogue'!B31 | C33: ='Metric Catalogue'!C31 | D33: ='Metric Catalogue'!D31 | E33: ='Metric Catalogue'!E31 | F33: =IFERROR(INDEX('3 Screen Updates'!$L$5:$L$39,MATCH($A33&"|"&F$6&"|"&$C$3,'3 Screen Updates'!$F$5:$F$39,0)),"") | G33: =IFERROR(INDEX('3 Screen Updates'!$L$5:$L$39,MATCH($A33&"|"&G$6&"|"&$C$3,'3 Screen Updates'!$F$5:$F$39,0)),"") | H33: =IFERROR(INDEX('3 Screen Updates'!$L$5:$L$39,MATCH($A33&"|"&H$6&"|"&$C$3,'3 Screen Updates'!$F$5:$F$39,0)),"") | I33: =IFERROR(INDEX('3 Screen Updates'!$L$5:$L$39,MATCH($A33&"|"&I$6&"|"&$C$3,'3 Screen Updates'!$F$5:$F$39,0)),"") | J33: =IFERROR(INDEX('3 Screen Updates'!$L$5:$L$39,MATCH($A33&"|"&J$6&"|"&$C$3,'3 Screen Updates'!$F$5:$F$39,0)),"") | K33: =IFERROR(INDEX('3 Screen Updates'!$L$5:$L$39,MATCH($A33&"|"&K$6&"|"&$C$3,'3 Screen Updates'!$F$5:$F$39,0)),"") | L33: =IFERROR(INDEX('3 Screen Updates'!$L$5:$L$39,MATCH($A33&"|"&L$6&"|"&$C$3,'3 Screen Updates'!$F$5:$F$39,0)),"") | M33: =IF(COUNT(F33:L33)=0,"",INDEX($F$6:$L$6,MATCH(IF($E33="Lower",MIN(F33:L33),MAX(F33:L33)),F33:L33,0))) | N33: =IF(OR(F33="",COUNT(F33:L33)=0),"",IF($E33="Lower",COUNTIF(F33:L33,"<"&F33),COUNTIF(F33:L33,">"&F33))+1) | O33: =COUNT(F33:L33) | P33: =IF(OR(F33="",COUNT(F33:L33)<2),"",IF($E33="Lower",IF(MIN(F33:L33)=0,"",(F33-MIN(F33:L33))/MIN(F33:L33)),IF(MAX(F33:L33)=0,"",(MAX(F33:L33)-F33)/MAX(F33:L33))))
A34: ='Metric Catalogue'!A32 | B34: ='Metric Catalogue'!B32 | C34: ='Metric Catalogue'!C32 | D34: ='Metric Catalogue'!D32 | E34: ='Metric Catalogue'!E32 | F34: =IFERROR(INDEX('4 Offline'!$C$14:$I$14,MATCH(F$6,'4 Offline'!$C$4:$I$4,0)),"") | G34: =IFERROR(INDEX('4 Offline'!$C$14:$I$14,MATCH(G$6,'4 Offline'!$C$4:$I$4,0)),"") | H34: =IFERROR(INDEX('4 Offline'!$C$14:$I$14,MATCH(H$6,'4 Offline'!$C$4:$I$4,0)),"") | I34: =IFERROR(INDEX('4 Offline'!$C$14:$I$14,MATCH(I$6,'4 Offline'!$C$4:$I$4,0)),"") | J34: =IFERROR(INDEX('4 Offline'!$C$14:$I$14,MATCH(J$6,'4 Offline'!$C$4:$I$4,0)),"") | K34: =IFERROR(INDEX('4 Offline'!$C$14:$I$14,MATCH(K$6,'4 Offline'!$C$4:$I$4,0)),"") | L34: =IFERROR(INDEX('4 Offline'!$C$14:$I$14,MATCH(L$6,'4 Offline'!$C$4:$I$4,0)),"") | M34: =IF(COUNT(F34:L34)=0,"",INDEX($F$6:$L$6,MATCH(IF($E34="Lower",MIN(F34:L34),MAX(F34:L34)),F34:L34,0))) | N34: =IF(OR(F34="",COUNT(F34:L34)=0),"",IF($E34="Lower",COUNTIF(F34:L34,"<"&F34),COUNTIF(F34:L34,">"&F34))+1) | O34: =COUNT(F34:L34) | P34: =IF(OR(F34="",COUNT(F34:L34)<2),"",IF($E34="Lower",IF(MIN(F34:L34)=0,"",(F34-MIN(F34:L34))/MIN(F34:L34)),IF(MAX(F34:L34)=0,"",(MAX(F34:L34)-F34)/MAX(F34:L34))))
A35: ='Metric Catalogue'!A33 | B35: ='Metric Catalogue'!B33 | C35: ='Metric Catalogue'!C33 | D35: ='Metric Catalogue'!D33 | E35: ='Metric Catalogue'!E33 | F35: =IFERROR(INDEX('5 Data Pointers'!$D$14:$J$14,MATCH(F$6,'5 Data Pointers'!$D$4:$J$4,0)),"") | G35: =IFERROR(INDEX('5 Data Pointers'!$D$14:$J$14,MATCH(G$6,'5 Data Pointers'!$D$4:$J$4,0)),"") | H35: =IFERROR(INDEX('5 Data Pointers'!$D$14:$J$14,MATCH(H$6,'5 Data Pointers'!$D$4:$J$4,0)),"") | I35: =IFERROR(INDEX('5 Data Pointers'!$D$14:$J$14,MATCH(I$6,'5 Data Pointers'!$D$4:$J$4,0)),"") | J35: =IFERROR(INDEX('5 Data Pointers'!$D$14:$J$14,MATCH(J$6,'5 Data Pointers'!$D$4:$J$4,0)),"") | K35: =IFERROR(INDEX('5 Data Pointers'!$D$14:$J$14,MATCH(K$6,'5 Data Pointers'!$D$4:$J$4,0)),"") | L35: =IFERROR(INDEX('5 Data Pointers'!$D$14:$J$14,MATCH(L$6,'5 Data Pointers'!$D$4:$J$4,0)),"") | M35: =IF(COUNT(F35:L35)=0,"",INDEX($F$6:$L$6,MATCH(IF($E35="Lower",MIN(F35:L35),MAX(F35:L35)),F35:L35,0))) | N35: =IF(OR(F35="",COUNT(F35:L35)=0),"",IF($E35="Lower",COUNTIF(F35:L35,"<"&F35),COUNTIF(F35:L35,">"&F35))+1) | O35: =COUNT(F35:L35) | P35: =IF(OR(F35="",COUNT(F35:L35)<2),"",IF($E35="Lower",IF(MIN(F35:L35)=0,"",(F35-MIN(F35:L35))/MIN(F35:L35)),IF(MAX(F35:L35)=0,"",(MAX(F35:L35)-F35)/MAX(F35:L35))))
A36: ='Metric Catalogue'!A34 | B36: ='Metric Catalogue'!B34 | C36: ='Metric Catalogue'!C34 | D36: ='Metric Catalogue'!D34 | E36: ='Metric Catalogue'!E34 | F36: =IFERROR(IF(INDEX('6 SDKs'!$B$5:$B$11,MATCH(F$6,'6 SDKs'!$A$5:$A$11,0))="","",INDEX('6 SDKs'!$B$5:$B$11,MATCH(F$6,'6 SDKs'!$A$5:$A$11,0))),"") | G36: =IFERROR(IF(INDEX('6 SDKs'!$B$5:$B$11,MATCH(G$6,'6 SDKs'!$A$5:$A$11,0))="","",INDEX('6 SDKs'!$B$5:$B$11,MATCH(G$6,'6 SDKs'!$A$5:$A$11,0))),"") | H36: =IFERROR(IF(INDEX('6 SDKs'!$B$5:$B$11,MATCH(H$6,'6 SDKs'!$A$5:$A$11,0))="","",INDEX('6 SDKs'!$B$5:$B$11,MATCH(H$6,'6 SDKs'!$A$5:$A$11,0))),"") | I36: =IFERROR(IF(INDEX('6 SDKs'!$B$5:$B$11,MATCH(I$6,'6 SDKs'!$A$5:$A$11,0))="","",INDEX('6 SDKs'!$B$5:$B$11,MATCH(I$6,'6 SDKs'!$A$5:$A$11,0))),"") | J36: =IFERROR(IF(INDEX('6 SDKs'!$B$5:$B$11,MATCH(J$6,'6 SDKs'!$A$5:$A$11,0))="","",INDEX('6 SDKs'!$B$5:$B$11,MATCH(J$6,'6 SDKs'!$A$5:$A$11,0))),"") | K36: =IFERROR(IF(INDEX('6 SDKs'!$B$5:$B$11,MATCH(K$6,'6 SDKs'!$A$5:$A$11,0))="","",INDEX('6 SDKs'!$B$5:$B$11,MATCH(K$6,'6 SDKs'!$A$5:$A$11,0))),"") | L36: =IFERROR(IF(INDEX('6 SDKs'!$B$5:$B$11,MATCH(L$6,'6 SDKs'!$A$5:$A$11,0))="","",INDEX('6 SDKs'!$B$5:$B$11,MATCH(L$6,'6 SDKs'!$A$5:$A$11,0))),"") | M36: =IF(COUNT(F36:L36)=0,"",INDEX($F$6:$L$6,MATCH(IF($E36="Lower",MIN(F36:L36),MAX(F36:L36)),F36:L36,0))) | N36: =IF(OR(F36="",COUNT(F36:L36)=0),"",IF($E36="Lower",COUNTIF(F36:L36,"<"&F36),COUNTIF(F36:L36,">"&F36))+1) | O36: =COUNT(F36:L36) | P36: =IF(OR(F36="",COUNT(F36:L36)<2),"",IF($E36="Lower",IF(MIN(F36:L36)=0,"",(F36-MIN(F36:L36))/MIN(F36:L36)),IF(MAX(F36:L36)=0,"",(MAX(F36:L36)-F36)/MAX(F36:L36))))
A37: ='Metric Catalogue'!A35 | B37: ='Metric Catalogue'!B35 | C37: ='Metric Catalogue'!C35 | D37: ='Metric Catalogue'!D35 | E37: ='Metric Catalogue'!E35 | F37: =IFERROR(IF(INDEX('6 SDKs'!$C$5:$C$11,MATCH(F$6,'6 SDKs'!$A$5:$A$11,0))="","",INDEX('6 SDKs'!$C$5:$C$11,MATCH(F$6,'6 SDKs'!$A$5:$A$11,0))),"") | G37: =IFERROR(IF(INDEX('6 SDKs'!$C$5:$C$11,MATCH(G$6,'6 SDKs'!$A$5:$A$11,0))="","",INDEX('6 SDKs'!$C$5:$C$11,MATCH(G$6,'6 SDKs'!$A$5:$A$11,0))),"") | H37: =IFERROR(IF(INDEX('6 SDKs'!$C$5:$C$11,MATCH(H$6,'6 SDKs'!$A$5:$A$11,0))="","",INDEX('6 SDKs'!$C$5:$C$11,MATCH(H$6,'6 SDKs'!$A$5:$A$11,0))),"") | I37: =IFERROR(IF(INDEX('6 SDKs'!$C$5:$C$11,MATCH(I$6,'6 SDKs'!$A$5:$A$11,0))="","",INDEX('6 SDKs'!$C$5:$C$11,MATCH(I$6,'6 SDKs'!$A$5:$A$11,0))),"") | J37: =IFERROR(IF(INDEX('6 SDKs'!$C$5:$C$11,MATCH(J$6,'6 SDKs'!$A$5:$A$11,0))="","",INDEX('6 SDKs'!$C$5:$C$11,MATCH(J$6,'6 SDKs'!$A$5:$A$11,0))),"") | K37: =IFERROR(IF(INDEX('6 SDKs'!$C$5:$C$11,MATCH(K$6,'6 SDKs'!$A$5:$A$11,0))="","",INDEX('6 SDKs'!$C$5:$C$11,MATCH(K$6,'6 SDKs'!$A$5:$A$11,0))),"") | L37: =IFERROR(IF(INDEX('6 SDKs'!$C$5:$C$11,MATCH(L$6,'6 SDKs'!$A$5:$A$11,0))="","",INDEX('6 SDKs'!$C$5:$C$11,MATCH(L$6,'6 SDKs'!$A$5:$A$11,0))),"") | M37: =IF(COUNT(F37:L37)=0,"",INDEX($F$6:$L$6,MATCH(IF($E37="Lower",MIN(F37:L37),MAX(F37:L37)),F37:L37,0))) | N37: =IF(OR(F37="",COUNT(F37:L37)=0),"",IF($E37="Lower",COUNTIF(F37:L37,"<"&F37),COUNTIF(F37:L37,">"&F37))+1) | O37: =COUNT(F37:L37) | P37: =IF(OR(F37="",COUNT(F37:L37)<2),"",IF($E37="Lower",IF(MIN(F37:L37)=0,"",(F37-MIN(F37:L37))/MIN(F37:L37)),IF(MAX(F37:L37)=0,"",(MAX(F37:L37)-F37)/MAX(F37:L37))))
A38: ='Metric Catalogue'!A36 | B38: ='Metric Catalogue'!B36 | C38: ='Metric Catalogue'!C36 | D38: ='Metric Catalogue'!D36 | E38: ='Metric Catalogue'!E36 | F38: =IFERROR(IF(INDEX('6 SDKs'!$D$5:$D$11,MATCH(F$6,'6 SDKs'!$A$5:$A$11,0))="","",INDEX('6 SDKs'!$D$5:$D$11,MATCH(F$6,'6 SDKs'!$A$5:$A$11,0))),"") | G38: =IFERROR(IF(INDEX('6 SDKs'!$D$5:$D$11,MATCH(G$6,'6 SDKs'!$A$5:$A$11,0))="","",INDEX('6 SDKs'!$D$5:$D$11,MATCH(G$6,'6 SDKs'!$A$5:$A$11,0))),"") | H38: =IFERROR(IF(INDEX('6 SDKs'!$D$5:$D$11,MATCH(H$6,'6 SDKs'!$A$5:$A$11,0))="","",INDEX('6 SDKs'!$D$5:$D$11,MATCH(H$6,'6 SDKs'!$A$5:$A$11,0))),"") | I38: =IFERROR(IF(INDEX('6 SDKs'!$D$5:$D$11,MATCH(I$6,'6 SDKs'!$A$5:$A$11,0))="","",INDEX('6 SDKs'!$D$5:$D$11,MATCH(I$6,'6 SDKs'!$A$5:$A$11,0))),"") | J38: =IFERROR(IF(INDEX('6 SDKs'!$D$5:$D$11,MATCH(J$6,'6 SDKs'!$A$5:$A$11,0))="","",INDEX('6 SDKs'!$D$5:$D$11,MATCH(J$6,'6 SDKs'!$A$5:$A$11,0))),"") | K38: =IFERROR(IF(INDEX('6 SDKs'!$D$5:$D$11,MATCH(K$6,'6 SDKs'!$A$5:$A$11,0))="","",INDEX('6 SDKs'!$D$5:$D$11,MATCH(K$6,'6 SDKs'!$A$5:$A$11,0))),"") | L38: =IFERROR(IF(INDEX('6 SDKs'!$D$5:$D$11,MATCH(L$6,'6 SDKs'!$A$5:$A$11,0))="","",INDEX('6 SDKs'!$D$5:$D$11,MATCH(L$6,'6 SDKs'!$A$5:$A$11,0))),"") | M38: =IF(COUNT(F38:L38)=0,"",INDEX($F$6:$L$6,MATCH(IF($E38="Lower",MIN(F38:L38),MAX(F38:L38)),F38:L38,0))) | N38: =IF(OR(F38="",COUNT(F38:L38)=0),"",IF($E38="Lower",COUNTIF(F38:L38,"<"&F38),COUNTIF(F38:L38,">"&F38))+1) | O38: =COUNT(F38:L38) | P38: =IF(OR(F38="",COUNT(F38:L38)<2),"",IF($E38="Lower",IF(MIN(F38:L38)=0,"",(F38-MIN(F38:L38))/MIN(F38:L38)),IF(MAX(F38:L38)=0,"",(MAX(F38:L38)-F38)/MAX(F38:L38))))
A39: ='Metric Catalogue'!A37 | B39: ='Metric Catalogue'!B37 | C39: ='Metric Catalogue'!C37 | D39: ='Metric Catalogue'!D37 | E39: ='Metric Catalogue'!E37 | F39: =IFERROR(IF(INDEX('6 SDKs'!$E$5:$E$11,MATCH(F$6,'6 SDKs'!$A$5:$A$11,0))="","",INDEX('6 SDKs'!$E$5:$E$11,MATCH(F$6,'6 SDKs'!$A$5:$A$11,0))),"") | G39: =IFERROR(IF(INDEX('6 SDKs'!$E$5:$E$11,MATCH(G$6,'6 SDKs'!$A$5:$A$11,0))="","",INDEX('6 SDKs'!$E$5:$E$11,MATCH(G$6,'6 SDKs'!$A$5:$A$11,0))),"") | H39: =IFERROR(IF(INDEX('6 SDKs'!$E$5:$E$11,MATCH(H$6,'6 SDKs'!$A$5:$A$11,0))="","",INDEX('6 SDKs'!$E$5:$E$11,MATCH(H$6,'6 SDKs'!$A$5:$A$11,0))),"") | I39: =IFERROR(IF(INDEX('6 SDKs'!$E$5:$E$11,MATCH(I$6,'6 SDKs'!$A$5:$A$11,0))="","",INDEX('6 SDKs'!$E$5:$E$11,MATCH(I$6,'6 SDKs'!$A$5:$A$11,0))),"") | J39: =IFERROR(IF(INDEX('6 SDKs'!$E$5:$E$11,MATCH(J$6,'6 SDKs'!$A$5:$A$11,0))="","",INDEX('6 SDKs'!$E$5:$E$11,MATCH(J$6,'6 SDKs'!$A$5:$A$11,0))),"") | K39: =IFERROR(IF(INDEX('6 SDKs'!$E$5:$E$11,MATCH(K$6,'6 SDKs'!$A$5:$A$11,0))="","",INDEX('6 SDKs'!$E$5:$E$11,MATCH(K$6,'6 SDKs'!$A$5:$A$11,0))),"") | L39: =IFERROR(IF(INDEX('6 SDKs'!$E$5:$E$11,MATCH(L$6,'6 SDKs'!$A$5:$A$11,0))="","",INDEX('6 SDKs'!$E$5:$E$11,MATCH(L$6,'6 SDKs'!$A$5:$A$11,0))),"") | M39: =IF(COUNT(F39:L39)=0,"",INDEX($F$6:$L$6,MATCH(IF($E39="Lower",MIN(F39:L39),MAX(F39:L39)),F39:L39,0))) | N39: =IF(OR(F39="",COUNT(F39:L39)=0),"",IF($E39="Lower",COUNTIF(F39:L39,"<"&F39),COUNTIF(F39:L39,">"&F39))+1) | O39: =COUNT(F39:L39) | P39: =IF(OR(F39="",COUNT(F39:L39)<2),"",IF($E39="Lower",IF(MIN(F39:L39)=0,"",(F39-MIN(F39:L39))/MIN(F39:L39)),IF(MAX(F39:L39)=0,"",(MAX(F39:L39)-F39)/MAX(F39:L39))))
A40: ='Metric Catalogue'!A38 | B40: ='Metric Catalogue'!B38 | C40: ='Metric Catalogue'!C38 | D40: ='Metric Catalogue'!D38 | E40: ='Metric Catalogue'!E38 | F40: =IFERROR(INDEX('7 RAM & Storage'!$L$5:$L$67,MATCH($A40&"|"&F$6&"|"&$C$3,'7 RAM & Storage'!$F$5:$F$67,0)),"") | G40: =IFERROR(INDEX('7 RAM & Storage'!$L$5:$L$67,MATCH($A40&"|"&G$6&"|"&$C$3,'7 RAM & Storage'!$F$5:$F$67,0)),"") | H40: =IFERROR(INDEX('7 RAM & Storage'!$L$5:$L$67,MATCH($A40&"|"&H$6&"|"&$C$3,'7 RAM & Storage'!$F$5:$F$67,0)),"") | I40: =IFERROR(INDEX('7 RAM & Storage'!$L$5:$L$67,MATCH($A40&"|"&I$6&"|"&$C$3,'7 RAM & Storage'!$F$5:$F$67,0)),"") | J40: =IFERROR(INDEX('7 RAM & Storage'!$L$5:$L$67,MATCH($A40&"|"&J$6&"|"&$C$3,'7 RAM & Storage'!$F$5:$F$67,0)),"") | K40: =IFERROR(INDEX('7 RAM & Storage'!$L$5:$L$67,MATCH($A40&"|"&K$6&"|"&$C$3,'7 RAM & Storage'!$F$5:$F$67,0)),"") | L40: =IFERROR(INDEX('7 RAM & Storage'!$L$5:$L$67,MATCH($A40&"|"&L$6&"|"&$C$3,'7 RAM & Storage'!$F$5:$F$67,0)),"") | M40: =IF(COUNT(F40:L40)=0,"",INDEX($F$6:$L$6,MATCH(IF($E40="Lower",MIN(F40:L40),MAX(F40:L40)),F40:L40,0))) | N40: =IF(OR(F40="",COUNT(F40:L40)=0),"",IF($E40="Lower",COUNTIF(F40:L40,"<"&F40),COUNTIF(F40:L40,">"&F40))+1) | O40: =COUNT(F40:L40) | P40: =IF(OR(F40="",COUNT(F40:L40)<2),"",IF($E40="Lower",IF(MIN(F40:L40)=0,"",(F40-MIN(F40:L40))/MIN(F40:L40)),IF(MAX(F40:L40)=0,"",(MAX(F40:L40)-F40)/MAX(F40:L40))))
A41: ='Metric Catalogue'!A39 | B41: ='Metric Catalogue'!B39 | C41: ='Metric Catalogue'!C39 | D41: ='Metric Catalogue'!D39 | E41: ='Metric Catalogue'!E39 | F41: =IFERROR(INDEX('7 RAM & Storage'!$L$5:$L$67,MATCH($A41&"|"&F$6&"|"&$C$3,'7 RAM & Storage'!$F$5:$F$67,0)),"") | G41: =IFERROR(INDEX('7 RAM & Storage'!$L$5:$L$67,MATCH($A41&"|"&G$6&"|"&$C$3,'7 RAM & Storage'!$F$5:$F$67,0)),"") | H41: =IFERROR(INDEX('7 RAM & Storage'!$L$5:$L$67,MATCH($A41&"|"&H$6&"|"&$C$3,'7 RAM & Storage'!$F$5:$F$67,0)),"") | I41: =IFERROR(INDEX('7 RAM & Storage'!$L$5:$L$67,MATCH($A41&"|"&I$6&"|"&$C$3,'7 RAM & Storage'!$F$5:$F$67,0)),"") | J41: =IFERROR(INDEX('7 RAM & Storage'!$L$5:$L$67,MATCH($A41&"|"&J$6&"|"&$C$3,'7 RAM & Storage'!$F$5:$F$67,0)),"") | K41: =IFERROR(INDEX('7 RAM & Storage'!$L$5:$L$67,MATCH($A41&"|"&K$6&"|"&$C$3,'7 RAM & Storage'!$F$5:$F$67,0)),"") | L41: =IFERROR(INDEX('7 RAM & Storage'!$L$5:$L$67,MATCH($A41&"|"&L$6&"|"&$C$3,'7 RAM & Storage'!$F$5:$F$67,0)),"") | M41: =IF(COUNT(F41:L41)=0,"",INDEX($F$6:$L$6,MATCH(IF($E41="Lower",MIN(F41:L41),MAX(F41:L41)),F41:L41,0))) | N41: =IF(OR(F41="",COUNT(F41:L41)=0),"",IF($E41="Lower",COUNTIF(F41:L41,"<"&F41),COUNTIF(F41:L41,">"&F41))+1) | O41: =COUNT(F41:L41) | P41: =IF(OR(F41="",COUNT(F41:L41)<2),"",IF($E41="Lower",IF(MIN(F41:L41)=0,"",(F41-MIN(F41:L41))/MIN(F41:L41)),IF(MAX(F41:L41)=0,"",(MAX(F41:L41)-F41)/MAX(F41:L41))))
A42: ='Metric Catalogue'!A40 | B42: ='Metric Catalogue'!B40 | C42: ='Metric Catalogue'!C40 | D42: ='Metric Catalogue'!D40 | E42: ='Metric Catalogue'!E40 | F42: =IFERROR(INDEX('7 RAM & Storage'!$L$5:$L$67,MATCH($A42&"|"&F$6&"|"&$C$3,'7 RAM & Storage'!$F$5:$F$67,0)),"") | G42: =IFERROR(INDEX('7 RAM & Storage'!$L$5:$L$67,MATCH($A42&"|"&G$6&"|"&$C$3,'7 RAM & Storage'!$F$5:$F$67,0)),"") | H42: =IFERROR(INDEX('7 RAM & Storage'!$L$5:$L$67,MATCH($A42&"|"&H$6&"|"&$C$3,'7 RAM & Storage'!$F$5:$F$67,0)),"") | I42: =IFERROR(INDEX('7 RAM & Storage'!$L$5:$L$67,MATCH($A42&"|"&I$6&"|"&$C$3,'7 RAM & Storage'!$F$5:$F$67,0)),"") | J42: =IFERROR(INDEX('7 RAM & Storage'!$L$5:$L$67,MATCH($A42&"|"&J$6&"|"&$C$3,'7 RAM & Storage'!$F$5:$F$67,0)),"") | K42: =IFERROR(INDEX('7 RAM & Storage'!$L$5:$L$67,MATCH($A42&"|"&K$6&"|"&$C$3,'7 RAM & Storage'!$F$5:$F$67,0)),"") | L42: =IFERROR(INDEX('7 RAM & Storage'!$L$5:$L$67,MATCH($A42&"|"&L$6&"|"&$C$3,'7 RAM & Storage'!$F$5:$F$67,0)),"") | M42: =IF(COUNT(F42:L42)=0,"",INDEX($F$6:$L$6,MATCH(IF($E42="Lower",MIN(F42:L42),MAX(F42:L42)),F42:L42,0))) | N42: =IF(OR(F42="",COUNT(F42:L42)=0),"",IF($E42="Lower",COUNTIF(F42:L42,"<"&F42),COUNTIF(F42:L42,">"&F42))+1) | O42: =COUNT(F42:L42) | P42: =IF(OR(F42="",COUNT(F42:L42)<2),"",IF($E42="Lower",IF(MIN(F42:L42)=0,"",(F42-MIN(F42:L42))/MIN(F42:L42)),IF(MAX(F42:L42)=0,"",(MAX(F42:L42)-F42)/MAX(F42:L42))))
A43: ='Metric Catalogue'!A41 | B43: ='Metric Catalogue'!B41 | C43: ='Metric Catalogue'!C41 | D43: ='Metric Catalogue'!D41 | E43: ='Metric Catalogue'!E41 | F43: =IFERROR(INDEX('7 RAM & Storage'!$L$5:$L$67,MATCH($A43&"|"&F$6&"|"&$C$3,'7 RAM & Storage'!$F$5:$F$67,0)),"") | G43: =IFERROR(INDEX('7 RAM & Storage'!$L$5:$L$67,MATCH($A43&"|"&G$6&"|"&$C$3,'7 RAM & Storage'!$F$5:$F$67,0)),"") | H43: =IFERROR(INDEX('7 RAM & Storage'!$L$5:$L$67,MATCH($A43&"|"&H$6&"|"&$C$3,'7 RAM & Storage'!$F$5:$F$67,0)),"") | I43: =IFERROR(INDEX('7 RAM & Storage'!$L$5:$L$67,MATCH($A43&"|"&I$6&"|"&$C$3,'7 RAM & Storage'!$F$5:$F$67,0)),"") | J43: =IFERROR(INDEX('7 RAM & Storage'!$L$5:$L$67,MATCH($A43&"|"&J$6&"|"&$C$3,'7 RAM & Storage'!$F$5:$F$67,0)),"") | K43: =IFERROR(INDEX('7 RAM & Storage'!$L$5:$L$67,MATCH($A43&"|"&K$6&"|"&$C$3,'7 RAM & Storage'!$F$5:$F$67,0)),"") | L43: =IFERROR(INDEX('7 RAM & Storage'!$L$5:$L$67,MATCH($A43&"|"&L$6&"|"&$C$3,'7 RAM & Storage'!$F$5:$F$67,0)),"") | M43: =IF(COUNT(F43:L43)=0,"",INDEX($F$6:$L$6,MATCH(IF($E43="Lower",MIN(F43:L43),MAX(F43:L43)),F43:L43,0))) | N43: =IF(OR(F43="",COUNT(F43:L43)=0),"",IF($E43="Lower",COUNTIF(F43:L43,"<"&F43),COUNTIF(F43:L43,">"&F43))+1) | O43: =COUNT(F43:L43) | P43: =IF(OR(F43="",COUNT(F43:L43)<2),"",IF($E43="Lower",IF(MIN(F43:L43)=0,"",(F43-MIN(F43:L43))/MIN(F43:L43)),IF(MAX(F43:L43)=0,"",(MAX(F43:L43)-F43)/MAX(F43:L43))))
...

Sheet Scorecard
A1: Scorecard — Overall Ranking
A2: Each metric is scored 0–100 (best app = 100, worst = 0), averaged per category, then weighted into one overall score. Weights come from weights.json.
A3: ="Device: "&Summary!C3
A4: Leaderboard
A5: Rank | B5: App | C5: Overall score (0–100) | D5: Data coverage
A6: 1 | B6: =IFERROR(INDEX($C$16:$I$16,MATCH(LARGE($C$33:$I$33,1),$C$33:$I$33,0)),"") | C6: =IFERROR(INDEX($C$30:$I$30,MATCH(LARGE($C$33:$I$33,1),$C$33:$I$33,0)),"") | D6: =IFERROR(INDEX($C$31:$I$31,MATCH(LARGE($C$33:$I$33,1),$C$33:$I$33,0)),"")
A7: 2 | B7: =IFERROR(INDEX($C$16:$I$16,MATCH(LARGE($C$33:$I$33,2),$C$33:$I$33,0)),"") | C7: =IFERROR(INDEX($C$30:$I$30,MATCH(LARGE($C$33:$I$33,2),$C$33:$I$33,0)),"") | D7: =IFERROR(INDEX($C$31:$I$31,MATCH(LARGE($C$33:$I$33,2),$C$33:$I$33,0)),"")
A8: 3 | B8: =IFERROR(INDEX($C$16:$I$16,MATCH(LARGE($C$33:$I$33,3),$C$33:$I$33,0)),"") | C8: =IFERROR(INDEX($C$30:$I$30,MATCH(LARGE($C$33:$I$33,3),$C$33:$I$33,0)),"") | D8: =IFERROR(INDEX($C$31:$I$31,MATCH(LARGE($C$33:$I$33,3),$C$33:$I$33,0)),"")
A9: 4 | B9: =IFERROR(INDEX($C$16:$I$16,MATCH(LARGE($C$33:$I$33,4),$C$33:$I$33,0)),"") | C9: =IFERROR(INDEX($C$30:$I$30,MATCH(LARGE($C$33:$I$33,4),$C$33:$I$33,0)),"") | D9: =IFERROR(INDEX($C$31:$I$31,MATCH(LARGE($C$33:$I$33,4),$C$33:$I$33,0)),"")
A10: 5 | B10: =IFERROR(INDEX($C$16:$I$16,MATCH(LARGE($C$33:$I$33,5),$C$33:$I$33,0)),"") | C10: =IFERROR(INDEX($C$30:$I$30,MATCH(LARGE($C$33:$I$33,5),$C$33:$I$33,0)),"") | D10: =IFERROR(INDEX($C$31:$I$31,MATCH(LARGE($C$33:$I$33,5),$C$33:$I$33,0)),"")
A11: 6 | B11: =IFERROR(INDEX($C$16:$I$16,MATCH(LARGE($C$33:$I$33,6),$C$33:$I$33,0)),"") | C11: =IFERROR(INDEX($C$30:$I$30,MATCH(LARGE($C$33:$I$33,6),$C$33:$I$33,0)),"") | D11: =IFERROR(INDEX($C$31:$I$31,MATCH(LARGE($C$33:$I$33,6),$C$33:$I$33,0)),"")
A12: 7 | B12: =IFERROR(INDEX($C$16:$I$16,MATCH(LARGE($C$33:$I$33,7),$C$33:$I$33,0)),"") | C12: =IFERROR(INDEX($C$30:$I$30,MATCH(LARGE($C$33:$I$33,7),$C$33:$I$33,0)),"") | D12: =IFERROR(INDEX($C$31:$I$31,MATCH(LARGE($C$33:$I$33,7),$C$33:$I$33,0)),"")
A15: Category scores (weights from weights.json, read-only here) | L15: Helper: weight × score (don't edit) | T15: Helper: weight used (don't edit)
A16: Category | B16: Weight | C16: RISE | D16: Kite | E16: Groww | F16: Angel One | G16: INDmoney | H16: Kotak Neo | I16: SAHI | L16: RISE | M16: Kite | N16: Groww | O16: Angel One | P16: INDmoney | Q16: Kotak Neo | R16: SAHI | T16: RISE | U16: Kite | V16: Groww | W16: Angel One | X16: INDmoney | Y16: Kotak Neo | Z16: SAHI
A17: Loading Time | B17: 20 | C17: =IFERROR(AVERAGEIFS(C$38:C$87,$B$38:$B$87,$A17),"") | D17: =IFERROR(AVERAGEIFS(D$38:D$87,$B$38:$B$87,$A17),"") | E17: =IFERROR(AVERAGEIFS(E$38:E$87,$B$38:$B$87,$A17),"") | F17: =IFERROR(AVERAGEIFS(F$38:F$87,$B$38:$B$87,$A17),"") | G17: =IFERROR(AVERAGEIFS(G$38:G$87,$B$38:$B$87,$A17),"") | H17: =IFERROR(AVERAGEIFS(H$38:H$87,$B$38:$B$87,$A17),"") | I17: =IFERROR(AVERAGEIFS(I$38:I$87,$B$38:$B$87,$A17),"") | L17: =IF(ISNUMBER(C17),$B17*C17,"") | M17: =IF(ISNUMBER(D17),$B17*D17,"") | N17: =IF(ISNUMBER(E17),$B17*E17,"") | O17: =IF(ISNUMBER(F17),$B17*F17,"") | P17: =IF(ISNUMBER(G17),$B17*G17,"") | Q17: =IF(ISNUMBER(H17),$B17*H17,"") | R17: =IF(ISNUMBER(I17),$B17*I17,"") | T17: =IF(ISNUMBER(C17),$B17,"") | U17: =IF(ISNUMBER(D17),$B17,"") | V17: =IF(ISNUMBER(E17),$B17,"") | W17: =IF(ISNUMBER(F17),$B17,"") | X17: =IF(ISNUMBER(G17),$B17,"") | Y17: =IF(ISNUMBER(H17),$B17,"") | Z17: =IF(ISNUMBER(I17),$B17,"")
A18: User-wise | B18: 5 | C18: =IFERROR(AVERAGEIFS(C$38:C$87,$B$38:$B$87,$A18),"") | D18: =IFERROR(AVERAGEIFS(D$38:D$87,$B$38:$B$87,$A18),"") | E18: =IFERROR(AVERAGEIFS(E$38:E$87,$B$38:$B$87,$A18),"") | F18: =IFERROR(AVERAGEIFS(F$38:F$87,$B$38:$B$87,$A18),"") | G18: =IFERROR(AVERAGEIFS(G$38:G$87,$B$38:$B$87,$A18),"") | H18: =IFERROR(AVERAGEIFS(H$38:H$87,$B$38:$B$87,$A18),"") | I18: =IFERROR(AVERAGEIFS(I$38:I$87,$B$38:$B$87,$A18),"") | L18: =IF(ISNUMBER(C18),$B18*C18,"") | M18: =IF(ISNUMBER(D18),$B18*D18,"") | N18: =IF(ISNUMBER(E18),$B18*E18,"") | O18: =IF(ISNUMBER(F18),$B18*F18,"") | P18: =IF(ISNUMBER(G18),$B18*G18,"") | Q18: =IF(ISNUMBER(H18),$B18*H18,"") | R18: =IF(ISNUMBER(I18),$B18*I18,"") | T18: =IF(ISNUMBER(C18),$B18,"") | U18: =IF(ISNUMBER(D18),$B18,"") | V18: =IF(ISNUMBER(E18),$B18,"") | W18: =IF(ISNUMBER(F18),$B18,"") | X18: =IF(ISNUMBER(G18),$B18,"") | Y18: =IF(ISNUMBER(H18),$B18,"") | Z18: =IF(ISNUMBER(I18),$B18,"")
A19: API / Network | B19: 5 | C19: =IFERROR(AVERAGEIFS(C$38:C$87,$B$38:$B$87,$A19),"") | D19: =IFERROR(AVERAGEIFS(D$38:D$87,$B$38:$B$87,$A19),"") | E19: =IFERROR(AVERAGEIFS(E$38:E$87,$B$38:$B$87,$A19),"") | F19: =IFERROR(AVERAGEIFS(F$38:F$87,$B$38:$B$87,$A19),"") | G19: =IFERROR(AVERAGEIFS(G$38:G$87,$B$38:$B$87,$A19),"") | H19: =IFERROR(AVERAGEIFS(H$38:H$87,$B$38:$B$87,$A19),"") | I19: =IFERROR(AVERAGEIFS(I$38:I$87,$B$38:$B$87,$A19),"") | L19: =IF(ISNUMBER(C19),$B19*C19,"") | M19: =IF(ISNUMBER(D19),$B19*D19,"") | N19: =IF(ISNUMBER(E19),$B19*E19,"") | O19: =IF(ISNUMBER(F19),$B19*F19,"") | P19: =IF(ISNUMBER(G19),$B19*G19,"") | Q19: =IF(ISNUMBER(H19),$B19*H19,"") | R19: =IF(ISNUMBER(I19),$B19*I19,"") | T19: =IF(ISNUMBER(C19),$B19,"") | U19: =IF(ISNUMBER(D19),$B19,"") | V19: =IF(ISNUMBER(E19),$B19,"") | W19: =IF(ISNUMBER(F19),$B19,"") | X19: =IF(ISNUMBER(G19),$B19,"") | Y19: =IF(ISNUMBER(H19),$B19,"") | Z19: =IF(ISNUMBER(I19),$B19,"")
A20: Offline | B20: 5 | C20: =IFERROR(AVERAGEIFS(C$38:C$87,$B$38:$B$87,$A20),"") | D20: =IFERROR(AVERAGEIFS(D$38:D$87,$B$38:$B$87,$A20),"") | E20: =IFERROR(AVERAGEIFS(E$38:E$87,$B$38:$B$87,$A20),"") | F20: =IFERROR(AVERAGEIFS(F$38:F$87,$B$38:$B$87,$A20),"") | G20: =IFERROR(AVERAGEIFS(G$38:G$87,$B$38:$B$87,$A20),"") | H20: =IFERROR(AVERAGEIFS(H$38:H$87,$B$38:$B$87,$A20),"") | I20: =IFERROR(AVERAGEIFS(I$38:I$87,$B$38:$B$87,$A20),"") | L20: =IF(ISNUMBER(C20),$B20*C20,"") | M20: =IF(ISNUMBER(D20),$B20*D20,"") | N20: =IF(ISNUMBER(E20),$B20*E20,"") | O20: =IF(ISNUMBER(F20),$B20*F20,"") | P20: =IF(ISNUMBER(G20),$B20*G20,"") | Q20: =IF(ISNUMBER(H20),$B20*H20,"") | R20: =IF(ISNUMBER(I20),$B20*I20,"") | T20: =IF(ISNUMBER(C20),$B20,"") | U20: =IF(ISNUMBER(D20),$B20,"") | V20: =IF(ISNUMBER(E20),$B20,"") | W20: =IF(ISNUMBER(F20),$B20,"") | X20: =IF(ISNUMBER(G20),$B20,"") | Y20: =IF(ISNUMBER(H20),$B20,"") | Z20: =IF(ISNUMBER(I20),$B20,"")
A21: Scroll & Gesture | B21: 15 | C21: =IFERROR(AVERAGEIFS(C$38:C$87,$B$38:$B$87,$A21),"") | D21: =IFERROR(AVERAGEIFS(D$38:D$87,$B$38:$B$87,$A21),"") | E21: =IFERROR(AVERAGEIFS(E$38:E$87,$B$38:$B$87,$A21),"") | F21: =IFERROR(AVERAGEIFS(F$38:F$87,$B$38:$B$87,$A21),"") | G21: =IFERROR(AVERAGEIFS(G$38:G$87,$B$38:$B$87,$A21),"") | H21: =IFERROR(AVERAGEIFS(H$38:H$87,$B$38:$B$87,$A21),"") | I21: =IFERROR(AVERAGEIFS(I$38:I$87,$B$38:$B$87,$A21),"") | L21: =IF(ISNUMBER(C21),$B21*C21,"") | M21: =IF(ISNUMBER(D21),$B21*D21,"") | N21: =IF(ISNUMBER(E21),$B21*E21,"") | O21: =IF(ISNUMBER(F21),$B21*F21,"") | P21: =IF(ISNUMBER(G21),$B21*G21,"") | Q21: =IF(ISNUMBER(H21),$B21*H21,"") | R21: =IF(ISNUMBER(I21),$B21*I21,"") | T21: =IF(ISNUMBER(C21),$B21,"") | U21: =IF(ISNUMBER(D21),$B21,"") | V21: =IF(ISNUMBER(E21),$B21,"") | W21: =IF(ISNUMBER(F21),$B21,"") | X21: =IF(ISNUMBER(G21),$B21,"") | Y21: =IF(ISNUMBER(H21),$B21,"") | Z21: =IF(ISNUMBER(I21),$B21,"")
A22: Screen Updation | B22: 15 | C22: =IFERROR(AVERAGEIFS(C$38:C$87,$B$38:$B$87,$A22),"") | D22: =IFERROR(AVERAGEIFS(D$38:D$87,$B$38:$B$87,$A22),"") | E22: =IFERROR(AVERAGEIFS(E$38:E$87,$B$38:$B$87,$A22),"") | F22: =IFERROR(AVERAGEIFS(F$38:F$87,$B$38:$B$87,$A22),"") | G22: =IFERROR(AVERAGEIFS(G$38:G$87,$B$38:$B$87,$A22),"") | H22: =IFERROR(AVERAGEIFS(H$38:H$87,$B$38:$B$87,$A22),"") | I22: =IFERROR(AVERAGEIFS(I$38:I$87,$B$38:$B$87,$A22),"") | L22: =IF(ISNUMBER(C22),$B22*C22,"") | M22: =IF(ISNUMBER(D22),$B22*D22,"") | N22: =IF(ISNUMBER(E22),$B22*E22,"") | O22: =IF(ISNUMBER(F22),$B22*F22,"") | P22: =IF(ISNUMBER(G22),$B22*G22,"") | Q22: =IF(ISNUMBER(H22),$B22*H22,"") | R22: =IF(ISNUMBER(I22),$B22*I22,"") | T22: =IF(ISNUMBER(C22),$B22,"") | U22: =IF(ISNUMBER(D22),$B22,"") | V22: =IF(ISNUMBER(E22),$B22,"") | W22: =IF(ISNUMBER(F22),$B22,"") | X22: =IF(ISNUMBER(G22),$B22,"") | Y22: =IF(ISNUMBER(H22),$B22,"") | Z22: =IF(ISNUMBER(I22),$B22,"")
